Workbook
Name _FX1: 伤害计算!$BK:$BK
Name _FX10: 伤害计算!$BT:$BT
Name _FX11: 伤害计算!$BU:$BU
Name _FX12: 伤害计算!$BV:$BV
Name _FX13: 伤害计算!$BW:$BW
Name _FX14: 伤害计算!$BX:$BX
Name _FX15: 伤害计算!$BY:$BY
Name _FX2: 伤害计算!$BL:$BL
Name _FX3: 伤害计算!$BN:$BN
Name _FX4: 伤害计算!$BN:$BN
Name _FX5: 伤害计算!$BO:$BO
Name _FX6: 伤害计算!$BP:$BP
Name _FX7: 伤害计算!$BQ:$BQ
Name _FX8: 伤害计算!$BR:$BR
Name _FX9: 伤害计算!$BS:$BS
Name BUFF: 伤害计算!$E$19:$E$33
Name 昂扬: 伤害计算!$C$16
Name 昂扬背水乘区: _xlfn.LAMBDA(_xlpm.a,_xlpm.b,(1+_xlpm.a*伤害计算!当前生命百分比)*(1+4*_xlpm.b*(1-MAX(0.25,伤害计算!当前生命百分比))*(1.5-MAX(0.25,伤害计算!当前生命百分比))))
Name 昂扬下限: 0
Name 白: 伤害计算!$BJ$1:$BJ$4
Name 包含: _xlfn.LAMBDA(_xlpm.值,_xlpm.数组,ISNUMBER(MATCH(_xlpm.值,_xlpm.数组,0)))
Name 背水: 伤害计算!$C$17
Name 背水下限: 0
Name 表取值: _xlfn.LAMBDA(_xlpm.键,_xlpm.表,_xlpm.表头,_xlpm.列,IFERROR(VLOOKUP(_xlpm.键,_xlpm.表,MATCH(_xlpm.列,_xlpm.表头,0),0),0))
Name 当前生命百分比: 伤害计算!$F$4
Name 敌方等级: 伤害计算!$J$3
Name 敌方抗性: 伤害计算!$M$4
Name 范围上限: 2.8
Name 防御乘区: _xlfn.LAMBDA(_xlpm.无视防御1,1-(1-(1-伤害计算!防御系数/(30+伤害计算!防御系数-MAX(0,MIN(20,MIN(80,伤害计算!敌方等级)-伤害计算!角色等级)))))*(1-_xlpm.无视防御1))
Name 防御系数: 伤害计算!$M$3
Name 和鸣增益: 伤害计算!$H$3
Name 基础: _xlfn.LAMBDA(_xlpm.键,IFERROR(INDIRECT("基础"&_xlpm.键),1))
Name 基础独立增伤: 伤害计算!$B$19
Name 基础防御: 伤害计算!$B$10
Name 基础攻击: 伤害计算!$B$7
Name 基础护盾: 伤害计算!$B$9
Name 基础近战暴击: 伤害计算!$B$65
Name 基础近战暴伤: 伤害计算!$B$66
Name 基础近战触发: 伤害计算!$B$69
Name 基础近战攻击: 伤害计算!$B$64
Name 基础近战攻速: 伤害计算!$B$70
Name 基础神智: 伤害计算!$B$11
Name 基础生命: 伤害计算!$B$8
Name 基础同律暴击: 伤害计算!$B$129
Name 基础同律暴伤: 伤害计算!$B$130
Name 基础同律触发: 伤害计算!$B$133
Name 基础同律多重: 伤害计算!$B$136
Name 基础同律攻击: 伤害计算!$B$128
Name 基础同律攻速: 伤害计算!$B$134
Name 基础无视防御: 伤害计算!$B$33
Name 基础远程暴击: 伤害计算!$B$98
Name 基础远程暴伤: 伤害计算!$B$99
Name 基础远程触发: 伤害计算!$B$102
Name 基础远程多重: 伤害计算!$B$104
Name 基础远程攻击: 伤害计算!$B$97
Name 基础远程攻速: 伤害计算!$B$103
Name 角色: 伤害计算!$B$3
Name 角色MOD: 伤害计算!$E$7:$E$14
Name 角色MOD等级乘数: _xlfn.MAP((伤害计算!$J$7:$J$14+1)/IF(伤害计算!$G$7:$G$14="金",11,IF(伤害计算!$G$7:$G$14="绿",4,6)),_xlfn.LAMBDA(_xlpm.a,IF(_xlpm.a>1,1,_xlpm.a)))
Name 角色等级: 伤害计算!$F$3

Sheet 伤害计算
A1: 二重螺旋配卡模拟器 (2025/12/2) | AV1: 角色MOD | AW1: 近战MOD | AX1: 远程MOD | AY1: 同律MOD | AZ1: 技能 | BA1: 近战倍率 | BB1: 远程倍率 | BC1: 同律倍率 | BD1: 属性 | BE1: 1 | BF1: 2 | BG1: 3 | BH1: 4 | BI1: 5 | BJ1: 0 | BK1: {=_xlfn.SEQUENCE(IFERROR(VLOOKUP(INDEX(BUFF,COLUMNS($BK1:BK1)),BUFF表[],MATCH("mx",BUFF表[#Headers],0),0),0)+1-IFERROR(VLOOKUP(INDEX(BUFF,COLUMNS($BK1:BK1)),BUFF表[],MATCH("lx",BUFF表[#Headers],0),0),0),1,IFERROR(VLOOKUP(INDEX(BUFF,COLUMNS($BK1:BK1)),BUFF表[],MATCH("lx",BUFF表[#Headers],0),0),0))} -> 1 | BL1: {=_xlfn.SEQUENCE(IFERROR(VLOOKUP(INDEX(BUFF,COLUMNS($BK1:BL1)),BUFF表[],MATCH("mx",BUFF表[#Headers],0),0),0)+1-IFERROR(VLOOKUP(INDEX(BUFF,COLUMNS($BK1:BL1)),BUFF表[],MATCH("lx",BUFF表[#Headers],0),0),0),1,IFERROR(VLOOKUP(INDEX(BUFF,COLUMNS($BK1:BL1)),BUFF表[],MATCH("lx",BUFF表[#Headers],0),0),0))} -> 0 | BM1: {=_xlfn.SEQUENCE(IFERROR(VLOOKUP(INDEX(BUFF,COLUMNS($BK1:BM1)),BUFF表[],MATCH("mx",BUFF表[#Headers],0),0),0)+1-IFERROR(VLOOKUP(INDEX(BUFF,COLUMNS($BK1:BM1)),BUFF表[],MATCH("lx",BUFF表[#Headers],0),0),0),1,IFERROR(VLOOKUP(INDEX(BUFF,COLUMNS($BK1:BM1)),BUFF表[],MATCH("lx",BUFF表[#Headers],0),0),0))} -> 0 | BN1: {=_xlfn.SEQUENCE(IFERROR(VLOOKUP(INDEX(BUFF,COLUMNS($BK1:BN1)),BUFF表[],MATCH("mx",BUFF表[#Headers],0),0),0)+1-IFERROR(VLOOKUP(INDEX(BUFF,COLUMNS($BK1:BN1)),BUFF表[],MATCH("lx",BUFF表[#Headers],0),0),0),1,IFERROR(VLOOKUP(INDEX(BUFF,COLUMNS($BK1:BN1)),BUFF表[],MATCH("lx",BUFF表[#Headers],0),0),0))} -> 1 | BO1: {=_xlfn.SEQUENCE(IFERROR(VLOOKUP(INDEX(BUFF,COLUMNS($BK1:BO1)),BUFF表[],MATCH("mx",BUFF表[#Headers],0),0),0)+1-IFERROR(VLOOKUP(INDEX(BUFF,COLUMNS($BK1:BO1)),BUFF表[],MATCH("lx",BUFF表[#Headers],0),0),0),1,IFERROR(VLOOKUP(INDEX(BUFF,COLUMNS($BK1:BO1)),BUFF表[],MATCH("lx",BUFF表[#Headers],0),0),0))} -> 0 | BP1: {=_xlfn.SEQUENCE(IFERROR(VLOOKUP(INDEX(BUFF,COLUMNS($BK1:BP1)),BUFF表[],MATCH("mx",BUFF表[#Headers],0),0),0)+1-IFERROR(VLOOKUP(INDEX(BUFF,COLUMNS($BK1:BP1)),BUFF表[],MATCH("lx",BUFF表[#Headers],0),0),0),1,IFERROR(VLOOKUP(INDEX(BUFF,COLUMNS($BK1:BP1)),BUFF表[],MATCH("lx",BUFF表[#Headers],0),0),0))} -> 0 | BQ1: {=_xlfn.SEQUENCE(IFERROR(VLOOKUP(INDEX(BUFF,COLUMNS($BK1:BQ1)),BUFF表[],MATCH("mx",BUFF表[#Headers],0),0),0)+1-IFERROR(VLOOKUP(INDEX(BUFF,COLUMNS($BK1:BQ1)),BUFF表[],MATCH("lx",BUFF表[#Headers],0),0),0),1,IFERROR(VLOOKUP(INDEX(BUFF,COLUMNS($BK1:BQ1)),BUFF表[],MATCH("lx",BUFF表[#Headers],0),0),0))} -> 0 | BR1: {=_xlfn.SEQUENCE(IFERROR(VLOOKUP(INDEX(BUFF,COLUMNS($BK1:BR1)),BUFF表[],MATCH("mx",BUFF表[#Headers],0),0),0)+1-IFERROR(VLOOKUP(INDEX(BUFF,COLUMNS($BK1:BR1)),BUFF表[],MATCH("lx",BUFF表[#Headers],0),0),0),1,IFERROR(VLOOKUP(INDEX(BUFF,COLUMNS($BK1:BR1)),BUFF表[],MATCH("lx",BUFF表[#Headers],0),0),0))} -> 0 | ... BY1: {=_xlfn.SEQUENCE(IFERROR(VLOOKUP(INDEX(BUFF,COLUMNS($BK1:BY1)),BUFF表[],MATCH("mx",BUFF表[#Headers],0),0),0)+1-IFERROR(VLOOKUP(INDEX(BUFF,COLUMNS($BK1:BY1)),BUFF表[],MATCH("lx",BUFF表[#Headers],0),0),0),1,IFERROR(VLOOKUP(INDEX(BUFF,COLUMNS($BK1:BY1)),BUFF表[],MATCH("lx",BUFF表[#Headers],0),0),0))} -> 0 | BZ1: {=_xlfn._xlws.FILTER(角色MOD表[品质],角色MOD表[名称]=INDEX(角色MOD,COLUMNS($BK1:BK1)))} -> 金 | CA1: {=_xlfn._xlws.FILTER(角色MOD表[品质],角色MOD表[名称]=INDEX(角色MOD,COLUMNS($BK1:BL1)))} -> 金 | CB1: {=_xlfn._xlws.FILTER(角色MOD表[品质],角色MOD表[名称]=INDEX(角色MOD,COLUMNS($BK1:BM1)))} -> #VALUE! | CC1: {=_xlfn._xlws.FILTER(角色MOD表[品质],角色MOD表[名称]=INDEX(角色MOD,COLUMNS($BK1:BN1)))} -> 金 | CD1: {=_xlfn._xlws.FILTER(角色MOD表[品质],角色MOD表[名称]=INDEX(角色MOD,COLUMNS($BK1:BO1)))} -> 金 | CE1: {=_xlfn._xlws.FILTER(角色MOD表[品质],角色MOD表[名称]=INDEX(角色MOD,COLUMNS($BK1:BP1)))} -> 金 | CF1: {=_xlfn._xlws.FILTER(角色MOD表[品质],角色MOD表[名称]=INDEX(角色MOD,COLUMNS($BK1:BQ1)))} -> 金 | CG1: {=_xlfn._xlws.FILTER(角色MOD表[品质],角色MOD表[名称]=INDEX(角色MOD,COLUMNS($BK1:BR1)))} -> 金
AV2: {=_xlfn._xlws.FILTER(角色MOD表[名称],(角色MOD表[属性]="")+(ISNUMBER(FIND($B$6,角色MOD表[属性]))))} -> 炽灼 | AW2: {=_xlfn._xlws.FILTER(武器MOD表[名称],((武器MOD表[限定]="")+(武器MOD表[限定]=$B$63)+(武器MOD表[限定]=$B$62))*(武器MOD表[类型]="近战武器"))} -> 攻势 | AX2: {=_xlfn._xlws.FILTER(武器MOD表[名称],((武器MOD表[限定]="")+(武器MOD表[限定]=$B$95)+(武器MOD表[限定]=$B$94))*(武器MOD表[类型]="远程武器"))} -> 攻势 | AY2: {=_xlfn._xlws.FILTER(武器MOD表[名称],武器MOD表[类型]=A123)} -> #VALUE! | AZ2: {=_xlfn._xlws.FILTER(技能表[名称],技能表[角色]=B3)} -> 鳞粉印记(E) | BA2: {=_xlfn._xlws.FILTER(近战倍率表[名称],近战倍率表[武器类型]=B62)} -> #VALUE! | BB2: {=_xlfn._xlws.FILTER(远程倍率表[名称],(远程倍率表[武器类型]=B94)*ISNUMBER(FIND(B92,远程倍率表[武器名称])))} -> 子弹伤害 | BC2: {=_xlfn.UNIQUE(_xlfn._xlws.FILTER(同律倍率表[名称],(同律倍率表[武器名称]=B123)*ISNUMBER(FIND(B123,同律倍率表[武器名称]))))} -> #VALUE! | BD2: 雷 | BE2: 雷云摧朽(满层) | BF2: 炽灼·决断 | BG2: 羽翼·永恒 | BH2: 炽灼·背水 | BI2: 炽灼·坚守 | BJ2: 1 | BK2: 2 | BM2: 1 | BN2: 2 | BP2: 1 | BR2: 1 | BT2: 1 | BU2: 1 | BV2: 1 | BW2: 1 | BX2: 1 | BZ2: 紫 | CA2: 紫 | CC2: 紫 | CD2: 紫 | CE2: 紫 | CF2: 紫 | CG2: 紫
A3: 角色 | B3: 赛琪 | C3: =IFERROR(VLOOKUP($B$3,角色表[],MATCH("近战",角色表[#Headers],0),0),"") -> 长柄 | D3: =IFERROR(VLOOKUP($B$3,角色表[],MATCH("远程",角色表[#Headers],0),0),"") -> 突击枪 | E3: 等级 | F3: 80 | G3: 和鸣增益 | H3: 2 | I3: 敌方等级 | J3: 180 | K3: 敌方类型 | L3: 小型 | M3: =IF($L$3="小型",13,IF($L$3="大型",20,30)) -> 13 | AV3: 涅槃 | AW3: 迅捷 | AX3: 迅捷 | AZ3: 鳞粉印记(E) | BD3: 水 | BE3: 水雾弥散 | BF3: 羽翼·决断 | BG3: 炽灼·权能 | BH3: 炽灼·鼓舞 | BI3: 炽灼·涅槃 | BJ3: 2 | BK3: 3 | BM3: 2 | BN3: 3 | BP3: 2 | BR3: 2 | BT3: 2 | BU3: 2 | BV3: 2 | BW3: 2 | BX3: 2
A4: 对象 | B4: 血量 | C4: 战姿失衡 | D4: 否 | E4: 当前生命百分比 | F4: 0.01 | G4: 属性克制 | H4: 弱点 | K4: 敌方抗性 | L4: 0 | M4: =L4+IF($H$4="弱点",-4,IF($H$4="非弱点",0.5,0)) -> -4 | AV4: 庇佑 | AW4: 领界 | AX4: 叠影 | AZ4: 浮光鳞粉(E) | BD4: 火 | BE4: 焚心野火(满层) | BF4: 涅槃·权能 | BG4: 炽灼·永恒(火) | BH4: 炽灼·坚守 | BI4: 炽灼·鼓舞 | BJ4: 3 | BK4: 4 | BM4: 3 | BN4: 4 | BP4: 3 | BR4: 3 | BT4: 3 | BU4: 3 | BV4: 3 | BW4: 3 | BX4: 3
A5: 角色面板 | D5: 角色MOD | T5: 收益计算辅助列 | AV5: 羽翼 | AW5: 锋锐 | AX5: 重压 | AZ5: 浮光鳞粉(E) | BD5: 风 | BE5: 薰风吐息(触发) | BF5: 炽灼·决断 | BG5: 羽翼·永恒 | BH5: 炽灼·背水 | BI5: 炽灼·坚守 | BJ5: 4 | BK5: 5 | BM5: 4 | BN5: 5 | BP5: 4 | BR5: 4 | BT5: 4 | BU5: 4 | BV5: 4 | BX5: 4
A6: 属性 | B6: =IFERROR(VLOOKUP($B$3,角色表[],MATCH(A6,角色表[#Headers],0),0),"") -> 风 | C6: {=取角色总属性("属性伤")} -> 0.38394 | D6: 收益 | E6: 名称 | F6: 系列 | G6: 品质 | H6: 极性 | I6: 耐受 | J6: 强化 | K6: 极化 | L6: 属性1 | N6: 属性2 | P6: 属性3 | R6: 属性4 | T6: 去除后期望 | U6: 攻击 | V6: 生命 | W6: 防御 | X6: 威力 | Y6: 耐久 | Z6: 效益 | AA6: 范围 | AB6: 昂扬 | AC6: 背水 | AD6: 增伤 | AE6: 技能伤害 | AF6: 属性穿透 | AG6: 独立增伤 | AH6: 无视防御 | AV6: 坚守 | AW6: 专注 | AX6: 专注 | AZ6: 腐草为萤(Q) | BD6: 光 | BE6: 流光交辉 | BF6: 炽灭 | BG6: 涅槃·决断 | BH6: 炽灼·永恒(光) | BI6: 炽灼·背水 | BJ6: 5 | BK6: 6 | BM6: 5 | BN6: 6 | BP6: 5 | BR6: 5 | BT6: 5 | BU6: 5 | BV6: 5 | BX6: 5
A7: 攻击 | B7: {=VLOOKUP($B$3,角色表[],MATCH("基础"&A7,角色表[#Headers],0),0)*IFERROR(INDEX({0.07967,0.2063,0.3021,0.4137,0.5291,0.6826,0.8136,1},,ROUNDUP($F$3/10,0)),1)} -> 351.46 | C7: {=取角色总属性(A7)*(1+$C$6)} -> 6096.6876 | D7: =(B$39-T7)/T7 -> 0.13651195 | E7: 全盛·背水 | F7: =IFERROR(VLOOKUP($E7,角色MOD表[],MATCH(F$6,角色MOD表[#Headers],0),0),"") -> 百首 | G7: 金 | H7: =IFERROR(VLOOKUP($E7,角色MOD表[],MATCH(H$6,角色MOD表[#Headers],0),0),"")&"" -> A | I7: =IF(AND(K7<>"",H7<>""),ROUNDUP(IF(H7=K7,IFERROR(VLOOKUP($E7,角色MOD表[],6,0)+$J7-IF($G7="金",10,IF($G7="绿",3,5)),0)/2,IFERROR(VLOOKUP($E7,角色MOD表[],6,0)+$J7-IF($G7="金",10,IF($G7="绿",3,5)),0)*1.5),0),IFERROR(VLOOKUP($E7,角色MOD表[],6,0)+$J7-IF($G7="金",10,IF($G7="绿",3,5)),0)) -> 23 | J7: 5 | L7: {=IFERROR(INDEX(角色MOD表[#Headers],SMALL(_xlfn._xlws.FILTER(COLUMN(_xlfn.DROP(INDEX(角色MOD表[],MATCH($E7,角色MOD表[名称],0),),,MATCH("耐受",角色MOD表[#Headers],0)))*(_xlfn.DROP(INDEX(角色MOD表[],MATCH($E7,角色MOD表[名称],0),),,6)<>""),COLUMN(_xlfn.DROP(INDEX(角色MOD表[],MATCH($E7,角色MOD表[名称],0),),,MATCH("耐受",角色MOD表[#Headers],0)))*(_xlfn.DROP(INDEX(角色MOD表[],MATCH($E7,角色MOD表[名称],0),),,6)<>"")<>0),ROUNDUP(COLUMNS($L7:L7)/2,0))),"")} -> 攻击 | M7: {=IFERROR(_xlfn.MAP(INDEX(INDEX(角色MOD表[],MATCH($E7,角色MOD表[名称],0),),SMALL(_xlfn._xlws.FILTER(COLUMN(_xlfn.DROP(INDEX(角色MOD表[],MATCH($E7,角色MOD表[名称],0),),,MATCH("耐受",角色MOD表[#Headers],0)))*(_xlfn.DROP(INDEX(角色MOD表[],MATCH($E7,角色MOD表[名称],0),),,MATCH("耐受",角色MOD表[#Headers],0))<>""),COLUMN(_xlfn.DROP(INDEX(角色MOD表[],MATCH($E7,角色MOD表[名称],0),),,MATCH("耐受",角色MOD表[#Headers],0)))*(_xlfn.DROP(INDEX(角色MOD表[],MATCH($E7,角色MOD表[名称],0),),,MATCH("耐受",角色MOD表[#Headers],0))<>"")<>0),ROUNDUP(COLUMNS($L7:L7)/2,0))),_xlfn.LAMBDA(_xlpm.x,IFERROR(IF(ISNUMBER(MATCH($F7,{"百首","狮鹫","契约者"},0)),1+SUM(IFERROR(BUFF层数乘数*VLOOKUP(BUFF,BUFF表[],MATCH("MOD属性",BUFF表[#Headers],0),0),0)),1)*MIN(1,($J7+1)/IF($G7="金",11,IF($G7="绿",4,6)))*_xlpm.x,_xlpm.x))),"")} -> 0.85512 | N7: {=IFERROR(INDEX(角色MOD表[#Headers],SMALL(_xlfn._xlws.FILTER(COLUMN(_xlfn.DROP(INDEX(角色MOD表[],MATCH($E7,角色MOD表[名称],0),),,MATCH("耐受",角色MOD表[#Headers],0)))*(_xlfn.DROP(INDEX(角色MOD表[],MATCH($E7,角色MOD表[名称],0),),,6)<>""),COLUMN(_xlfn.DROP(INDEX(角色MOD表[],MATCH($E7,角色MOD表[名称],0),),,MATCH("耐受",角色MOD表[#Headers],0)))*(_xlfn.DROP(INDEX(角色MOD表[],MATCH($E7,角色MOD表[名称],0),),,6)<>"")<>0),ROUNDUP(COLUMNS($L7:N7)/2,0))),"")} -> 生命 | O7: {=IFERROR(_xlfn.MAP(INDEX(INDEX(角色MOD表[],MATCH($E7,角色MOD表[名称],0),),SMALL(_xlfn._xlws.FILTER(COLUMN(_xlfn.DROP(INDEX(角色MOD表[],MATCH($E7,角色MOD表[名称],0),),,MATCH("耐受",角色MOD表[#Headers],0)))*(_xlfn.DROP(INDEX(角色MOD表[],MATCH($E7,角色MOD表[名称],0),),,MATCH("耐受",角色MOD表[#Headers],0))<>""),COLUMN(_xlfn.DROP(INDEX(角色MOD表[],MATCH($E7,角色MOD表[名称],0),),,MATCH("耐受",角色MOD表[#Headers],0)))*(_xlfn.DROP(INDEX(角色MOD表[],MATCH($E7,角色MOD表[名称],0),),,MATCH("耐受",角色MOD表[#Headers],0))<>"")<>0),ROUNDUP(COLUMNS($L7:N7)/2,0))),_xlfn.LAMBDA(_xlpm.x,IFERROR(IF(ISNUMBER(MATCH($F7,{"百首","狮鹫","契约者"},0)),1+SUM(IFERROR(BUFF层数乘数*VLOOKUP(BUFF,BUFF表[],MATCH("MOD属性",BUFF表[#Headers],0),0),0)),1)*MIN(1,($J7+1)/IF($G7="金",11,IF($G7="绿",4,6)))*_xlpm.x,_xlpm.x))),"")} -> 0.85512 | P7: {=IFERROR(INDEX(角色MOD表[#Headers],SMALL(_xlfn._xlws.FILTER(COLUMN(_xlfn.DROP(INDEX(角色MOD表[],MATCH($E7,角色MOD表[名称],0),),,MATCH("耐受",角色MOD表[#Headers],0)))*(_xlfn.DROP(INDEX(角色MOD表[],MATCH($E7,角色MOD表[名称],0),),,6)<>""),COLUMN(_xlfn.DROP(INDEX(角色MOD表[],MATCH($E7,角色MOD表[名称],0),),,MATCH("耐受",角色MOD表[#Headers],0)))*(_xlfn.DROP(INDEX(角色MOD表[],MATCH($E7,角色MOD表[名称],0),),,6)<>"")<>0),ROUNDUP(COLUMNS($L7:P7)/2,0))),"")} -> 防御 | Q7: {=IFERROR(_xlfn.MAP(INDEX(INDEX(角色MOD表[],MATCH($E7,角色MOD表[名称],0),),SMALL(_xlfn._xlws.FILTER(COLUMN(_xlfn.DROP(INDEX(角色MOD表[],MATCH($E7,角色MOD表[名称],0),),,MATCH("耐受",角色MOD表[#Headers],0)))*(_xlfn.DROP(INDEX(角色MOD表[],MATCH($E7,角色MOD表[名称],0),),,MATCH("耐受",角色MOD表[#Headers],0))<>""),COLUMN(_xlfn.DROP(INDEX(角色MOD表[],MATCH($E7,角色MOD表[名称],0),),,MATCH("耐受",角色MOD表[#Headers],0)))*(_xlfn.DROP(INDEX(角色MOD表[],MATCH($E7,角色MOD表[名称],0),),,MATCH("耐受",角色MOD表[#Headers],0))<>"")<>0),ROUNDUP(COLUMNS($L7:P7)/2,0))),_xlfn.LAMBDA(_xlpm.x,IFERROR(IF(ISNUMBER(MATCH($F7,{"百首","狮鹫","契约者"},0)),1+SUM(IFERROR(BUFF层数乘数*VLOOKUP(BUFF,BUFF表[],MATCH("MOD属性",BUFF表[#Headers],0),0),0)),1)*MIN(1,($J7+1)/IF($G7="金",11,IF($G7="绿",4,6)))*_xlpm.x,_xlpm.x))),"")} -> 0.85512 | R7: {=IFERROR(INDEX(角色MOD表[#Headers],SMALL(_xlfn._xlws.FILTER(COLUMN(_xlfn.DROP(INDEX(角色MOD表[],MATCH($E7,角色MOD表[名称],0),),,MATCH("耐受",角色MOD表[#Headers],0)))*(_xlfn.DROP(INDEX(角色MOD表[],MATCH($E7,角色MOD表[名称],0),),,6)<>""),COLUMN(_xlfn.DROP(INDEX(角色MOD表[],MATCH($E7,角色MOD表[名称],0),),,MATCH("耐受",角色MOD表[#Headers],0)))*(_xlfn.DROP(INDEX(角色MOD表[],MATCH($E7,角色MOD表[名称],0),),,6)<>"")<>0),ROUNDUP(COLUMNS($L7:R7)/2,0))),"")} -> 背水 | S7: {=IFERROR(_xlfn.MAP(INDEX(INDEX(角色MOD表[],MATCH($E7,角色MOD表[名称],0),),SMALL(_xlfn._xlws.FILTER(COLUMN(_xlfn.DROP(INDEX(角色MOD表[],MATCH($E7,角色MOD表[名称],0),),,MATCH("耐受",角色MOD表[#Headers],0)))*(_xlfn.DROP(INDEX(角色MOD表[],MATCH($E7,角色MOD表[名称],0),),,MATCH("耐受",角色MOD表[#Headers],0))<>""),COLUMN(_xlfn.DROP(INDEX(角色MOD表[],MATCH($E7,角色MOD表[名称],0),),,MATCH("耐受",角色MOD表[#Headers],0)))*(_xlfn.DROP(INDEX(角色MOD表[],MATCH($E7,角色MOD表[名称],0),),,MATCH("耐受",角色MOD表[#Headers],0))<>"")<>0),ROUNDUP(COLUMNS($L7:R7)/2,0))),_xlfn.LAMBDA(_xlpm.x,IFERROR(IF(ISNUMBER(MATCH($F7,{"百首","狮鹫","契约者"},0)),1+SUM(IFERROR(BUFF层数乘数*VLOOKUP(BUFF,BUFF表[],MATCH("MOD属性",BUFF表[#Headers],0),0),0)),1)*MIN(1,($J7+1)/IF($G7="金",11,IF($G7="绿",4,6)))*_xlpm.x,_xlpm.x))),"")} -> 0.06108 | T7: {=X7*SUM(B$24*U7,B$26*V7,B$25*W7,B$27)*昂扬背水乘区(AB7,AC7)*SUM(1,AD7,AE7)*(1-敌方抗性+AF7)*(1+AG7)/IF($A$39="DPMP",ROUNDUP($B$30*(2-Z7),0),1)/IF($A$39="DPSMP",ROUNDUP($B$31*MAX(0.25,(2-Z7)/Y7),0),1)*防御乘区(AH7)} -> 777426.76 | U7: {=删MOD取角色属性(U$6,ROWS($J$7:$J7))*(1+删MOD取角色属性("属性伤",ROWS($J$7:$J7)))} -> 5680.7577 | V7: {=删MOD取角色属性(V$6,ROWS($J$7:$J7))} -> 2637 | W7: {=删MOD取角色属性(W$6,ROWS($J$7:$J7))} -> 756 | X7: {=删MOD取角色属性(X$6,ROWS($J$7:$J7))} -> 8.01554 | Y7: {=删MOD取角色属性(Y$6,ROWS($J$7:$J7))} -> 1.2 | Z7: {=删MOD取角色属性(Z$6,ROWS($J$7:$J7))} -> 0 | AA7: {=删MOD取角色属性(AA$6,ROWS($J$7:$J7))} -> 1.33594 | AB7: {=删MOD取角色属性(AB$6,ROWS($J$7:$J7))} -> 0 | AC7: {=删MOD取角色属性(AC$6,ROWS($J$7:$J7))} -> 0.769 | ... AH7: {=删MOD取角色属性(AH$6,ROWS($J$7:$J7))} -> 0 | AV7: 凛风·极昼 | AW7: 盛怒 | AX7: 盛怒 | AZ7: 腐草为萤(Q) | BD7: 暗 | BE7: 虚妄献察 | BF7: 炽灭 | BG7: 炽灼·昂扬 | BH7: 炽灼·权能 | BI7: 坚守·鼓舞 | BJ7: 6 | BK7: 7 | BM7: 6 | BN7: 7 | BT7: 6 | BU7: 6 | BV7: 6 | BX7: 6
A8: 生命 | B8: {=VLOOKUP($B$3,角色表[],MATCH("基础"&A8,角色表[#Headers],0),0)*IFERROR(INDEX({0.07967,0.2063,0.3021,0.4137,0.5291,0.6826,0.8136,1},,ROUNDUP($F$3/10,0)),1)} -> 879 | C8: {=取角色总属性(A8)} -> 3388.6505 | D8: =(B$39-T8)/T8 -> 0.3884694 | E8: 凛风·燎原 | F8: =IFERROR(VLOOKUP($E8,角色MOD表[],MATCH(F$6,角色MOD表[#Headers],0),0),"") -> 狮鹫 | G8: =IFERROR(VLOOKUP($E8,角色MOD表[],MATCH(G$6,角色MOD表[#Headers],0),0),"") -> 金 | H8: =IFERROR(VLOOKUP($E8,角色MOD表[],MATCH(H$6,角色MOD表[#Headers],0),0),"")&"" -> V | I8: =IF(AND(K8<>"",H8<>""),ROUNDUP(IF(H8=K8,IFERROR(VLOOKUP($E8,角色MOD表[],6,0)+$J8-IF($G8="金",10,IF($G8="绿",3,5)),0)/2,IFERROR(VLOOKUP($E8,角色MOD表[],6,0)+$J8-IF($G8="金",10,IF($G8="绿",3,5)),0)*1.5),0),IFERROR(VLOOKUP($E8,角色MOD表[],6,0)+$J8-IF($G8="金",10,IF($G8="绿",3,5)),0)) -> 25 | J8: 10 | L8: {=IFERROR(INDEX(角色MOD表[#Headers],SMALL(_xlfn._xlws.FILTER(COLUMN(_xlfn.DROP(INDEX(角色MOD表[],MATCH($E8,角色MOD表[名称],0),),,MATCH("耐受",角色MOD表[#Headers],0)))*(_xlfn.DROP(INDEX(角色MOD表[],MATCH($E8,角色MOD表[名称],0),),,6)<>""),COLUMN(_xlfn.DROP(INDEX(角色MOD表[],MATCH($E8,角色MOD表[名称],0),),,MATCH("耐受",角色MOD表[#Headers],0)))*(_xlfn.DROP(INDEX(角色MOD表[],MATCH($E8,角色MOD表[名称],0),),,6)<>"")<>0),ROUNDUP(COLUMNS($L8:L8)/2,0))),"")} -> 威力 | M8: {=IFERROR(_xlfn.MAP(INDEX(INDEX(角色MOD表[],MATCH($E8,角色MOD表[名称],0),),SMALL(_xlfn._xlws.FILTER(COLUMN(_xlfn.DROP(INDEX(角色MOD表[],MATCH($E8,角色MOD表[名称],0),),,MATCH("耐受",角色MOD表[#Headers],0)))*(_xlfn.DROP(INDEX(角色MOD表[],MATCH($E8,角色MOD表[名称],0),),,MATCH("耐受",角色MOD表[#Headers],0))<>""),COLUMN(_xlfn.DROP(INDEX(角色MOD表[],MATCH($E8,角色MOD表[名称],0),),,MATCH("耐受",角色MOD表[#Headers],0)))*(_xlfn.DROP(INDEX(角色MOD表[],MATCH($E8,角色MOD表[名称],0),),,MATCH("耐受",角色MOD表[#Headers],0))<>"")<>0),ROUNDUP(COLUMNS($L8:L8)/2,0))),_xlfn.LAMBDA(_xlpm.x,IFERROR(IF(ISNUMBER(MATCH($F8,{"百首","狮鹫","契约者"},0)),1+SUM(IFERROR(BUFF层数乘数*VLOOKUP(BUFF,BUFF表[],MATCH("MOD属性",BUFF表[#Headers],0),0),0)),1)*MIN(1,($J8+1)/IF($G8="金",11,IF($G8="绿",4,6)))*_xlpm.x,_xlpm.x))),"")} -> 0.33594 | N8: {=IFERROR(INDEX(角色MOD表[#Headers],SMALL(_xlfn._xlws.FILTER(COLUMN(_xlfn.DROP(INDEX(角色MOD表[],MATCH($E8,角色MOD表[名称],0),),,MATCH("耐受",角色MOD表[#Headers],0)))*(_xlfn.DROP(INDEX(角色MOD表[],MATCH($E8,角色MOD表[名称],0),),,6)<>""),COLUMN(_xlfn.DROP(INDEX(角色MOD表[],MATCH($E8,角色MOD表[名称],0),),,MATCH("耐受",角色MOD表[#Headers],0)))*(_xlfn.DROP(INDEX(角色MOD表[],MATCH($E8,角色MOD表[名称],0),),,6)<>"")<>0),ROUNDUP(COLUMNS($L8:N8)/2,0))),"")} -> 范围 | O8: {=IFERROR(_xlfn.MAP(INDEX(INDEX(角色MOD表[],MATCH($E8,角色MOD表[名称],0),),SMALL(_xlfn._xlws.FILTER(COLUMN(_xlfn.DROP(INDEX(角色MOD表[],MATCH($E8,角色MOD表[名称],0),),,MATCH("耐受",角色MOD表[#Headers],0)))*(_xlfn.DROP(INDEX(角色MOD表[],MATCH($E8,角色MOD表[名称],0),),,MATCH("耐受",角色MOD表[#Headers],0))<>""),COLUMN(_xlfn.DROP(INDEX(角色MOD表[],MATCH($E8,角色MOD表[名称],0),),,MATCH("耐受",角色MOD表[#Headers],0)))*(_xlfn.DROP(INDEX(角色MOD表[],MATCH($E8,角色MOD表[名称],0),),,MATCH("耐受",角色MOD表[#Headers],0))<>"")<>0),ROUNDUP(COLUMNS($L8:N8)/2,0))),_xlfn.LAMBDA(_xlpm.x,IFERROR(IF(ISNUMBER(MATCH($F8,{"百首","狮鹫","契约者"},0)),1+SUM(IFERROR(BUFF层数乘数*VLOOKUP(BUFF,BUFF表[],MATCH("MOD属性",BUFF表[#Headers],0),0),0)),1)*MIN(1,($J8+1)/IF($G8="金",11,IF($G8="绿",4,6)))*_xlpm.x,_xlpm.x))),"")} -> 0.33594 | P8: {=IFERROR(INDEX(角色MOD表[#Headers],SMALL(_xlfn._xlws.FILTER(COLUMN(_xlfn.DROP(INDEX(角色MOD表[],MATCH($E8,角色MOD表[名称],0),),,MATCH("耐受",角色MOD表[#Headers],0)))*(_xlfn.DROP(INDEX(角色MOD表[],MATCH($E8,角色MOD表[名称],0),),,6)<>""),COLUMN(_xlfn.DROP(INDEX(角色MOD表[],MATCH($E8,角色MOD表[名称],0),),,MATCH("耐受",角色MOD表[#Headers],0)))*(_xlfn.DROP(INDEX(角色MOD表[],MATCH($E8,角色MOD表[名称],0),),,6)<>"")<>0),ROUNDUP(COLUMNS($L8:P8)/2,0))),"")} -> 属性伤 | Q8: {=IFERROR(_xlfn.MAP(INDEX(INDEX(角色MOD表[],MATCH($E8,角色MOD表[名称],0),),SMALL(_xlfn._xlws.FILTER(COLUMN(_xlfn.DROP(INDEX(角色MOD表[],MATCH($E8,角色MOD表[名称],0),),,MATCH("耐受",角色MOD表[#Headers],0)))*(_xlfn.DROP(INDEX(角色MOD表[],MATCH($E8,角色MOD表[名称],0),),,MATCH("耐受",角色MOD表[#Headers],0))<>""),COLUMN(_xlfn.DROP(INDEX(角色MOD表[],MATCH($E8,角色MOD表[名称],0),),,MATCH("耐受",角色MOD表[#Headers],0)))*(_xlfn.DROP(INDEX(角色MOD表[],MATCH($E8,角色MOD表[名称],0),),,MATCH("耐受",角色MOD表[#Headers],0))<>"")<>0),ROUNDUP(COLUMNS($L8:P8)/2,0))),_xlfn.LAMBDA(_xlpm.x,IFERROR(IF(ISNUMBER(MATCH($F8,{"百首","狮鹫","契约者"},0)),1+SUM(IFERROR(BUFF层数乘数*VLOOKUP(BUFF,BUFF表[],MATCH("MOD属性",BUFF表[#Headers],0),0),0)),1)*MIN(1,($J8+1)/IF($G8="金",11,IF($G8="绿",4,6)))*_xlpm.x,_xlpm.x))),"")} -> 0.33594 | R8: {=IFERROR(INDEX(角色MOD表[#Headers],SMALL(_xlfn._xlws.FILTER(COLUMN(_xlfn.DROP(INDEX(角色MOD表[],MATCH($E8,角色MOD表[名称],0),),,MATCH("耐受",角色MOD表[#Headers],0)))*(_xlfn.DROP(INDEX(角色MOD表[],MATCH($E8,角色MOD表[名称],0),),,6)<>""),COLUMN(_xlfn.DROP(INDEX(角色MOD表[],MATCH($E8,角色MOD表[名称],0),),,MATCH("耐受",角色MOD表[#Headers],0)))*(_xlfn.DROP(INDEX(角色MOD表[],MATCH($E8,角色MOD表[名称],0),),,6)<>"")<>0),ROUNDUP(COLUMNS($L8:R8)/2,0))),"")} | S8: {=IFERROR(_xlfn.MAP(INDEX(INDEX(角色MOD表[],MATCH($E8,角色MOD表[名称],0),),SMALL(_xlfn._xlws.FILTER(COLUMN(_xlfn.DROP(INDEX(角色MOD表[],MATCH($E8,角色MOD表[名称],0),),,MATCH("耐受",角色MOD表[#Headers],0)))*(_xlfn.DROP(INDEX(角色MOD表[],MATCH($E8,角色MOD表[名称],0),),,MATCH("耐受",角色MOD表[#Headers],0))<>""),COLUMN(_xlfn.DROP(INDEX(角色MOD表[],MATCH($E8,角色MOD表[名称],0),),,MATCH("耐受",角色MOD表[#Headers],0)))*(_xlfn.DROP(INDEX(角色MOD表[],MATCH($E8,角色MOD表[名称],0),),,MATCH("耐受",角色MOD表[#Headers],0))<>"")<>0),ROUNDUP(COLUMNS($L8:R8)/2,0))),_xlfn.LAMBDA(_xlpm.x,IFERROR(IF(ISNUMBER(MATCH($F8,{"百首","狮鹫","契约者"},0)),1+SUM(IFERROR(BUFF层数乘数*VLOOKUP(BUFF,BUFF表[],MATCH("MOD属性",BUFF表[#Headers],0),0),0)),1)*MIN(1,($J8+1)/IF($G8="金",11,IF($G8="绿",4,6)))*_xlpm.x,_xlpm.x))),"")} | T8: {=X8*SUM(B$24*U8,B$26*V8,B$25*W8,B$27)*昂扬背水乘区(AB8,AC8)*SUM(1,AD8,AE8)*(1-敌方抗性+AF8)*(1+AG8)/IF($A$39="DPMP",ROUNDUP($B$30*(2-Z8),0),1)/IF($A$39="DPSMP",ROUNDUP($B$31*MAX(0.25,(2-Z8)/Y8),0),1)*防御乘区(AH8)} -> 636351.66 | U8: {=删MOD取角色属性(U$6,ROWS($J$7:$J8))*(1+删MOD取角色属性("属性伤",ROWS($J$7:$J8)))} -> 4583.0207 | V8: {=删MOD取角色属性(V$6,ROWS($J$7:$J8))} -> 3388.6505 | W8: {=删MOD取角色属性(W$6,ROWS($J$7:$J8))} -> 971.49024 | X8: {=删MOD取角色属性(X$6,ROWS($J$7:$J8))} -> 7.6796 | Y8: {=删MOD取角色属性(Y$6,ROWS($J$7:$J8))} -> 1.2 | Z8: {=删MOD取角色属性(Z$6,ROWS($J$7:$J8))} -> 0 | AA8: {=删MOD取角色属性(AA$6,ROWS($J$7:$J8))} -> 1 | AB8: {=删MOD取角色属性(AB$6,ROWS($J$7:$J8))} -> 0 | AC8: {=删MOD取角色属性(AC$6,ROWS($J$7:$J8))} -> 0.83008 | ... AH8: {=删MOD取角色属性(AH$6,ROWS($J$7:$J8))} -> 0 | AV8: 凛风·燎原 | AW8: 缠缚 | AX8: 缠缚 | BJ8: 7 | BK8: 8 | BM8: 7 | BN8: 8 | BT8: 7 | BU8: 7 | BV8: 7 | BX8: 7
A9: 护盾 | B9: {=VLOOKUP($B$3,角色表[],MATCH("基础"&A9,角色表[#Headers],0),0)*IFERROR(INDEX({0.07967,0.2063,0.3021,0.4137,0.5291,0.6826,0.8136,1},,ROUNDUP($F$3/10,0)),1)} -> 1757 | C9: {=取角色总属性(A9)} -> 5271 | D9: =(B$39-T9)/T9 -> 0.36267096 | E9: 薰风吐息(触发) | F9: =IFERROR(VLOOKUP($E9,角色MOD表[],MATCH(F$6,角色MOD表[#Headers],0),0),"") | G9: =IFERROR(VLOOKUP($E9,角色MOD表[],MATCH(G$6,角色MOD表[#Headers],0),0),"") | H9: =IFERROR(VLOOKUP($E9,角色MOD表[],MATCH(H$6,角色MOD表[#Headers],0),0),"")&"" | I9: =IF(AND(K9<>"",H9<>""),ROUNDUP(IF(H9=K9,IFERROR(VLOOKUP($E9,角色MOD表[],6,0)+$J9-IF($G9="金",10,IF($G9="绿",3,5)),0)/2,IFERROR(VLOOKUP($E9,角色MOD表[],6,0)+$J9-IF($G9="金",10,IF($G9="绿",3,5)),0)*1.5),0),IFERROR(VLOOKUP($E9,角色MOD表[],6,0)+$J9-IF($G9="金",10,IF($G9="绿",3,5)),0)) -> 0 | J9: 10 | L9: {=IFERROR(INDEX(角色MOD表[#Headers],SMALL(_xlfn._xlws.FILTER(COLUMN(_xlfn.DROP(INDEX(角色MOD表[],MATCH($E9,角色MOD表[名称],0),),,MATCH("耐受",角色MOD表[#Headers],0)))*(_xlfn.DROP(INDEX(角色MOD表[],MATCH($E9,角色MOD表[名称],0),),,6)<>""),COLUMN(_xlfn.DROP(INDEX(角色MOD表[],MATCH($E9,角色MOD表[名称],0),),,MATCH("耐受",角色MOD表[#Headers],0)))*(_xlfn.DROP(INDEX(角色MOD表[],MATCH($E9,角色MOD表[名称],0),),,6)<>"")<>0),ROUNDUP(COLUMNS($L9:L9)/2,0))),"")} | M9: {=IFERROR(_xlfn.MAP(INDEX(INDEX(角色MOD表[],MATCH($E9,角色MOD表[名称],0),),SMALL(_xlfn._xlws.FILTER(COLUMN(_xlfn.DROP(INDEX(角色MOD表[],MATCH($E9,角色MOD表[名称],0),),,MATCH("耐受",角色MOD表[#Headers],0)))*(_xlfn.DROP(INDEX(角色MOD表[],MATCH($E9,角色MOD表[名称],0),),,MATCH("耐受",角色MOD表[#Headers],0))<>""),COLUMN(_xlfn.DROP(INDEX(角色MOD表[],MATCH($E9,角色MOD表[名称],0),),,MATCH("耐受",角色MOD表[#Headers],0)))*(_xlfn.DROP(INDEX(角色MOD表[],MATCH($E9,角色MOD表[名称],0),),,MATCH("耐受",角色MOD表[#Headers],0))<>"")<>0),ROUNDUP(COLUMNS($L9:L9)/2,0))),_xlfn.LAMBDA(_xlpm.x,IFERROR(IF(ISNUMBER(MATCH($F9,{"百首","狮鹫","契约者"},0)),1+SUM(IFERROR(BUFF层数乘数*VLOOKUP(BUFF,BUFF表[],MATCH("MOD属性",BUFF表[#Headers],0),0),0)),1)*MIN(1,($J9+1)/IF($G9="金",11,IF($G9="绿",4,6)))*_xlpm.x,_xlpm.x))),"")} | N9: {=IFERROR(INDEX(角色MOD表[#Headers],SMALL(_xlfn._xlws.FILTER(COLUMN(_xlfn.DROP(INDEX(角色MOD表[],MATCH($E9,角色MOD表[名称],0),),,MATCH("耐受",角色MOD表[#Headers],0)))*(_xlfn.DROP(INDEX(角色MOD表[],MATCH($E9,角色MOD表[名称],0),),,6)<>""),COLUMN(_xlfn.DROP(INDEX(角色MOD表[],MATCH($E9,角色MOD表[名称],0),),,MATCH("耐受",角色MOD表[#Headers],0)))*(_xlfn.DROP(INDEX(角色MOD表[],MATCH($E9,角色MOD表[名称],0),),,6)<>"")<>0),ROUNDUP(COLUMNS($L9:N9)/2,0))),"")} | O9: {=IFERROR(_xlfn.MAP(INDEX(INDEX(角色MOD表[],MATCH($E9,角色MOD表[名称],0),),SMALL(_xlfn._xlws.FILTER(COLUMN(_xlfn.DROP(INDEX(角色MOD表[],MATCH($E9,角色MOD表[名称],0),),,MATCH("耐受",角色MOD表[#Headers],0)))*(_xlfn.DROP(INDEX(角色MOD表[],MATCH($E9,角色MOD表[名称],0),),,MATCH("耐受",角色MOD表[#Headers],0))<>""),COLUMN(_xlfn.DROP(INDEX(角色MOD表[],MATCH($E9,角色MOD表[名称],0),),,MATCH("耐受",角色MOD表[#Headers],0)))*(_xlfn.DROP(INDEX(角色MOD表[],MATCH($E9,角色MOD表[名称],0),),,MATCH("耐受",角色MOD表[#Headers],0))<>"")<>0),ROUNDUP(COLUMNS($L9:N9)/2,0))),_xlfn.LAMBDA(_xlpm.x,IFERROR(IF(ISNUMBER(MATCH($F9,{"百首","狮鹫","契约者"},0)),1+SUM(IFERROR(BUFF层数乘数*VLOOKUP(BUFF,BUFF表[],MATCH("MOD属性",BUFF表[#Headers],0),0),0)),1)*MIN(1,($J9+1)/IF($G9="金",11,IF($G9="绿",4,6)))*_xlpm.x,_xlpm.x))),"")} | P9: {=IFERROR(INDEX(角色MOD表[#Headers],SMALL(_xlfn._xlws.FILTER(COLUMN(_xlfn.DROP(INDEX(角色MOD表[],MATCH($E9,角色MOD表[名称],0),),,MATCH("耐受",角色MOD表[#Headers],0)))*(_xlfn.DROP(INDEX(角色MOD表[],MATCH($E9,角色MOD表[名称],0),),,6)<>""),COLUMN(_xlfn.DROP(INDEX(角色MOD表[],MATCH($E9,角色MOD表[名称],0),),,MATCH("耐受",角色MOD表[#Headers],0)))*(_xlfn.DROP(INDEX(角色MOD表[],MATCH($E9,角色MOD表[名称],0),),,6)<>"")<>0),ROUNDUP(COLUMNS($L9:P9)/2,0))),"")} | Q9: {=IFERROR(_xlfn.MAP(INDEX(INDEX(角色MOD表[],MATCH($E9,角色MOD表[名称],0),),SMALL(_xlfn._xlws.FILTER(COLUMN(_xlfn.DROP(INDEX(角色MOD表[],MATCH($E9,角色MOD表[名称],0),),,MATCH("耐受",角色MOD表[#Headers],0)))*(_xlfn.DROP(INDEX(角色MOD表[],MATCH($E9,角色MOD表[名称],0),),,MATCH("耐受",角色MOD表[#Headers],0))<>""),COLUMN(_xlfn.DROP(INDEX(角色MOD表[],MATCH($E9,角色MOD表[名称],0),),,MATCH("耐受",角色MOD表[#Headers],0)))*(_xlfn.DROP(INDEX(角色MOD表[],MATCH($E9,角色MOD表[名称],0),),,MATCH("耐受",角色MOD表[#Headers],0))<>"")<>0),ROUNDUP(COLUMNS($L9:P9)/2,0))),_xlfn.LAMBDA(_xlpm.x,IFERROR(IF(ISNUMBER(MATCH($F9,{"百首","狮鹫","契约者"},0)),1+SUM(IFERROR(BUFF层数乘数*VLOOKUP(BUFF,BUFF表[],MATCH("MOD属性",BUFF表[#Headers],0),0),0)),1)*MIN(1,($J9+1)/IF($G9="金",11,IF($G9="绿",4,6)))*_xlpm.x,_xlpm.x))),"")} | R9: {=IFERROR(INDEX(角色MOD表[#Headers],SMALL(_xlfn._xlws.FILTER(COLUMN(_xlfn.DROP(INDEX(角色MOD表[],MATCH($E9,角色MOD表[名称],0),),,MATCH("耐受",角色MOD表[#Headers],0)))*(_xlfn.DROP(INDEX(角色MOD表[],MATCH($E9,角色MOD表[名称],0),),,6)<>""),COLUMN(_xlfn.DROP(INDEX(角色MOD表[],MATCH($E9,角色MOD表[名称],0),),,MATCH("耐受",角色MOD表[#Headers],0)))*(_xlfn.DROP(INDEX(角色MOD表[],MATCH($E9,角色MOD表[名称],0),),,6)<>"")<>0),ROUNDUP(COLUMNS($L9:R9)/2,0))),"")} | S9: {=IFERROR(_xlfn.MAP(INDEX(INDEX(角色MOD表[],MATCH($E9,角色MOD表[名称],0),),SMALL(_xlfn._xlws.FILTER(COLUMN(_xlfn.DROP(INDEX(角色MOD表[],MATCH($E9,角色MOD表[名称],0),),,MATCH("耐受",角色MOD表[#Headers],0)))*(_xlfn.DROP(INDEX(角色MOD表[],MATCH($E9,角色MOD表[名称],0),),,MATCH("耐受",角色MOD表[#Headers],0))<>""),COLUMN(_xlfn.DROP(INDEX(角色MOD表[],MATCH($E9,角色MOD表[名称],0),),,MATCH("耐受",角色MOD表[#Headers],0)))*(_xlfn.DROP(INDEX(角色MOD表[],MATCH($E9,角色MOD表[名称],0),),,MATCH("耐受",角色MOD表[#Headers],0))<>"")<>0),ROUNDUP(COLUMNS($L9:R9)/2,0))),_xlfn.LAMBDA(_xlpm.x,IFERROR(IF(ISNUMBER(MATCH($F9,{"百首","狮鹫","契约者"},0)),1+SUM(IFERROR(BUFF层数乘数*VLOOKUP(BUFF,BUFF表[],MATCH("MOD属性",BUFF表[#Headers],0),0),0)),1)*MIN(1,($J9+1)/IF($G9="金",11,IF($G9="绿",4,6)))*_xlpm.x,_xlpm.x))),"")} | T9: {=X9*SUM(B$24*U9,B$26*V9,B$25*W9,B$27)*昂扬背水乘区(AB9,AC9)*SUM(1,AD9,AE9)*(1-敌方抗性+AF9)*(1+AG9)/IF($A$39="DPMP",ROUNDUP($B$30*(2-Z9),0),1)/IF($A$39="DPSMP",ROUNDUP($B$31*MAX(0.25,(2-Z9)/Y9),0),1)*防御乘区(AH9)} -> 648399.23 | U9: {=删MOD取角色属性(U$6,ROWS($J$7:$J9))*(1+删MOD取角色属性("属性伤",ROWS($J$7:$J9)))} -> 6052.1237 | V9: {=删MOD取角色属性(V$6,ROWS($J$7:$J9))} -> 3388.6505 | W9: {=删MOD取角色属性(W$6,ROWS($J$7:$J9))} -> 971.49024 | X9: {=删MOD取角色属性(X$6,ROWS($J$7:$J9))} -> 5.92554 | Y9: {=删MOD取角色属性(Y$6,ROWS($J$7:$J9))} -> 1.2 | Z9: {=删MOD取角色属性(Z$6,ROWS($J$7:$J9))} -> 0 | AA9: {=删MOD取角色属性(AA$6,ROWS($J$7:$J9))} -> 1.33594 | AB9: {=删MOD取角色属性(AB$6,ROWS($J$7:$J9))} -> 0 | AC9: {=删MOD取角色属性(AC$6,ROWS($J$7:$J9))} -> 0.83008 | ... AH9: {=删MOD取角色属性(AH$6,ROWS($J$7:$J9))} -> 0 | AV9: 全盛·昂扬 | AW9: 攻势·专注 | AX9: 攻势·专注 | BJ9: 8 | BK9: 9 | BM9: 8 | BN9: 9 | BT9: 8 | BU9: 8 | BV9: 8 | BX9: 8
A10: 防御 | B10: {=VLOOKUP($B$3,角色表[],MATCH("基础"&A10,角色表[#Headers],0),0)*IFERROR(INDEX({0.07967,0.2063,0.3021,0.4137,0.5291,0.6826,0.8136,1},,ROUNDUP($F$3/10,0)),1)} -> 252 | C10: {=取角色总属性(A10)} -> 948.402 | D10: =(B$39-T10)/T10 -> 0.14976834 | E10: 炽灼·决断 | F10: =IFERROR(VLOOKUP($E10,角色MOD表[],MATCH(F$6,角色MOD表[#Headers],0),0),"") -> 契约者 | G10: =IFERROR(VLOOKUP($E10,角色MOD表[],MATCH(G$6,角色MOD表[#Headers],0),0),"") -> 金 | H10: =IFERROR(VLOOKUP($E10,角色MOD表[],MATCH(H$6,角色MOD表[#Headers],0),0),"")&"" -> V | I10: =IF(AND(K10<>"",H10<>""),ROUNDUP(IF(H10=K10,IFERROR(VLOOKUP($E10,角色MOD表[],6,0)+$J10-IF($G10="金",10,IF($G10="绿",3,5)),0)/2,IFERROR(VLOOKUP($E10,角色MOD表[],6,0)+$J10-IF($G10="金",10,IF($G10="绿",3,5)),0)*1.5),0),IFERROR(VLOOKUP($E10,角色MOD表[],6,0)+$J10-IF($G10="金",10,IF($G10="绿",3,5)),0)) -> 20 | J10: 10 | L10: {=IFERROR(INDEX(角色MOD表[#Headers],SMALL(_xlfn._xlws.FILTER(COLUMN(_xlfn.DROP(INDEX(角色MOD表[],MATCH($E10,角色MOD表[名称],0),),,MATCH("耐受",角色MOD表[#Headers],0)))*(_xlfn.DROP(INDEX(角色MOD表[],MATCH($E10,角色MOD表[名称],0),),,6)<>""),COLUMN(_xlfn.DROP(INDEX(角色MOD表[],MATCH($E10,角色MOD表[名称],0),),,MATCH("耐受",角色MOD表[#Headers],0)))*(_xlfn.DROP(INDEX(角色MOD表[],MATCH($E10,角色MOD表[名称],0),),,6)<>"")<>0),ROUNDUP(COLUMNS($L10:L10)/2,0))),"")} -> 威力 | M10: {=IFERROR(_xlfn.MAP(INDEX(INDEX(角色MOD表[],MATCH($E10,角色MOD表[名称],0),),SMALL(_xlfn._xlws.FILTER(COLUMN(_xlfn.DROP(INDEX(角色MOD表[],MATCH($E10,角色MOD表[名称],0),),,MATCH("耐受",角色MOD表[#Headers],0)))*(_xlfn.DROP(INDEX(角色MOD表[],MATCH($E10,角色MOD表[名称],0),),,MATCH("耐受",角色MOD表[#Headers],0))<>""),COLUMN(_xlfn.DROP(INDEX(角色MOD表[],MATCH($E10,角色MOD表[名称],0),),,MATCH("耐受",角色MOD表[#Headers],0)))*(_xlfn.DROP(INDEX(角色MOD表[],MATCH($E10,角色MOD表[名称],0),),,MATCH("耐受",角色MOD表[#Headers],0))<>"")<>0),ROUNDUP(COLUMNS($L10:L10)/2,0))),_xlfn.LAMBDA(_xlpm.x,IFERROR(IF(ISNUMBER(MATCH($F10,{"百首","狮鹫","契约者"},0)),1+SUM(IFERROR(BUFF层数乘数*VLOOKUP(BUFF,BUFF表[],MATCH("MOD属性",BUFF表[#Headers],0),0),0)),1)*MIN(1,($J10+1)/IF($G10="金",11,IF($G10="绿",4,6)))*_xlpm.x,_xlpm.x))),"")} -> 0.44792 | N10: {=IFERROR(INDEX(角色MOD表[#Headers],SMALL(_xlfn._xlws.FILTER(COLUMN(_xlfn.DROP(INDEX(角色MOD表[],MATCH($E10,角色MOD表[名称],0),),,MATCH("耐受",角色MOD表[#Headers],0)))*(_xlfn.DROP(INDEX(角色MOD表[],MATCH($E10,角色MOD表[名称],0),),,6)<>""),COLUMN(_xlfn.DROP(INDEX(角色MOD表[],MATCH($E10,角色MOD表[名称],0),),,MATCH("耐受",角色MOD表[#Headers],0)))*(_xlfn.DROP(INDEX(角色MOD表[],MATCH($E10,角色MOD表[名称],0),),,6)<>"")<>0),ROUNDUP(COLUMNS($L10:N10)/2,0))),"")} -> 攻击 | O10: {=IFERROR(_xlfn.MAP(INDEX(INDEX(角色MOD表[],MATCH($E10,角色MOD表[名称],0),),SMALL(_xlfn._xlws.FILTER(COLUMN(_xlfn.DROP(INDEX(角色MOD表[],MATCH($E10,角色MOD表[名称],0),),,MATCH("耐受",角色MOD表[#Headers],0)))*(_xlfn.DROP(INDEX(角色MOD表[],MATCH($E10,角色MOD表[名称],0),),,MATCH("耐受",角色MOD表[#Headers],0))<>""),COLUMN(_xlfn.DROP(INDEX(角色MOD表[],MATCH($E10,角色MOD表[名称],0),),,MATCH("耐受",角色MOD表[#Headers],0)))*(_xlfn.DROP(INDEX(角色MOD表[],MATCH($E10,角色MOD表[名称],0),),,MATCH("耐受",角色MOD表[#Headers],0))<>"")<>0),ROUNDUP(COLUMNS($L10:N10)/2,0))),_xlfn.LAMBDA(_xlpm.x,IFERROR(IF(ISNUMBER(MATCH($F10,{"百首","狮鹫","契约者"},0)),1+SUM(IFERROR(BUFF层数乘数*VLOOKUP(BUFF,BUFF表[],MATCH("MOD属性",BUFF表[#Headers],0),0),0)),1)*MIN(1,($J10+1)/IF($G10="金",11,IF($G10="绿",4,6)))*_xlpm.x,_xlpm.x))),"")} -> 0.89584 | P10: {=IFERROR(INDEX(角色MOD表[#Headers],SMALL(_xlfn._xlws.FILTER(COLUMN(_xlfn.DROP(INDEX(角色MOD表[],MATCH($E10,角色MOD表[名称],0),),,MATCH("耐受",角色MOD表[#Headers],0)))*(_xlfn.DROP(INDEX(角色MOD表[],MATCH($E10,角色MOD表[名称],0),),,6)<>""),COLUMN(_xlfn.DROP(INDEX(角色MOD表[],MATCH($E10,角色MOD表[名称],0),),,MATCH("耐受",角色MOD表[#Headers],0)))*(_xlfn.DROP(INDEX(角色MOD表[],MATCH($E10,角色MOD表[名称],0),),,6)<>"")<>0),ROUNDUP(COLUMNS($L10:P10)/2,0))),"")} | Q10: {=IFERROR(_xlfn.MAP(INDEX(INDEX(角色MOD表[],MATCH($E10,角色MOD表[名称],0),),SMALL(_xlfn._xlws.FILTER(COLUMN(_xlfn.DROP(INDEX(角色MOD表[],MATCH($E10,角色MOD表[名称],0),),,MATCH("耐受",角色MOD表[#Headers],0)))*(_xlfn.DROP(INDEX(角色MOD表[],MATCH($E10,角色MOD表[名称],0),),,MATCH("耐受",角色MOD表[#Headers],0))<>""),COLUMN(_xlfn.DROP(INDEX(角色MOD表[],MATCH($E10,角色MOD表[名称],0),),,MATCH("耐受",角色MOD表[#Headers],0)))*(_xlfn.DROP(INDEX(角色MOD表[],MATCH($E10,角色MOD表[名称],0),),,MATCH("耐受",角色MOD表[#Headers],0))<>"")<>0),ROUNDUP(COLUMNS($L10:P10)/2,0))),_xlfn.LAMBDA(_xlpm.x,IFERROR(IF(ISNUMBER(MATCH($F10,{"百首","狮鹫","契约者"},0)),1+SUM(IFERROR(BUFF层数乘数*VLOOKUP(BUFF,BUFF表[],MATCH("MOD属性",BUFF表[#Headers],0),0),0)),1)*MIN(1,($J10+1)/IF($G10="金",11,IF($G10="绿",4,6)))*_xlpm.x,_xlpm.x))),"")} | R10: {=IFERROR(INDEX(角色MOD表[#Headers],SMALL(_xlfn._xlws.FILTER(COLUMN(_xlfn.DROP(INDEX(角色MOD表[],MATCH($E10,角色MOD表[名称],0),),,MATCH("耐受",角色MOD表[#Headers],0)))*(_xlfn.DROP(INDEX(角色MOD表[],MATCH($E10,角色MOD表[名称],0),),,6)<>""),COLUMN(_xlfn.DROP(INDEX(角色MOD表[],MATCH($E10,角色MOD表[名称],0),),,MATCH("耐受",角色MOD表[#Headers],0)))*(_xlfn.DROP(INDEX(角色MOD表[],MATCH($E10,角色MOD表[名称],0),),,6)<>"")<>0),ROUNDUP(COLUMNS($L10:R10)/2,0))),"")} | S10: {=IFERROR(_xlfn.MAP(INDEX(INDEX(角色MOD表[],MATCH($E10,角色MOD表[名称],0),),SMALL(_xlfn._xlws.FILTER(COLUMN(_xlfn.DROP(INDEX(角色MOD表[],MATCH($E10,角色MOD表[名称],0),),,MATCH("耐受",角色MOD表[#Headers],0)))*(_xlfn.DROP(INDEX(角色MOD表[],MATCH($E10,角色MOD表[名称],0),),,MATCH("耐受",角色MOD表[#Headers],0))<>""),COLUMN(_xlfn.DROP(INDEX(角色MOD表[],MATCH($E10,角色MOD表[名称],0),),,MATCH("耐受",角色MOD表[#Headers],0)))*(_xlfn.DROP(INDEX(角色MOD表[],MATCH($E10,角色MOD表[名称],0),),,MATCH("耐受",角色MOD表[#Headers],0))<>"")<>0),ROUNDUP(COLUMNS($L10:R10)/2,0))),_xlfn.LAMBDA(_xlpm.x,IFERROR(IF(ISNUMBER(MATCH($F10,{"百首","狮鹫","契约者"},0)),1+SUM(IFERROR(BUFF层数乘数*VLOOKUP(BUFF,BUFF表[],MATCH("MOD属性",BUFF表[#Headers],0),0),0)),1)*MIN(1,($J10+1)/IF($G10="金",11,IF($G10="绿",4,6)))*_xlpm.x,_xlpm.x))),"")} | T10: {=X10*SUM(B$24*U10,B$26*V10,B$25*W10,B$27)*昂扬背水乘区(AB10,AC10)*SUM(1,AD10,AE10)*(1-敌方抗性+AF10)*(1+AG10)/IF($A$39="DPMP",ROUNDUP($B$30*(2-Z10),0),1)/IF($A$39="DPSMP",ROUNDUP($B$31*MAX(0.25,(2-Z10)/Y10),0),1)*防御乘区(AH10)} -> 768463.32 | U10: {=删MOD取角色属性(U$6,ROWS($J$7:$J10))*(1+删MOD取角色属性("属性伤",ROWS($J$7:$J10)))} -> 5616.3875 | V10: {=删MOD取角色属性(V$6,ROWS($J$7:$J10))} -> 3388.6505 | W10: {=删MOD取角色属性(W$6,ROWS($J$7:$J10))} -> 971.49024 | X10: {=删MOD取角色属性(X$6,ROWS($J$7:$J10))} -> 7.56762 | Y10: {=删MOD取角色属性(Y$6,ROWS($J$7:$J10))} -> 1.2 | Z10: {=删MOD取角色属性(Z$6,ROWS($J$7:$J10))} -> 0 | AA10: {=删MOD取角色属性(AA$6,ROWS($J$7:$J10))} -> 1.33594 | AB10: {=删MOD取角色属性(AB$6,ROWS($J$7:$J10))} -> 0 | AC10: {=删MOD取角色属性(AC$6,ROWS($J$7:$J10))} -> 0.83008 | ... AH10: {=删MOD取角色属性(AH$6,ROWS($J$7:$J10))} -> 0 | AV10: 全盛·背水 | AW10: 盛怒·缠缚 | AX10: 盛怒·缠缚 | BJ10: 9 | BK10: 10 | BM10: 9 | BN10: 10 | BT10: 9 | BU10: 9 | BV10: 9 | BX10: 9
A11: 神智 | B11: =VLOOKUP($B$3,角色表[],MATCH("基础"&A11,角色表[#Headers],0),0) -> 150 | C11: {=取角色总属性(A11)} -> 150 | D11: =(B$39-T11)/T11 -> 0.14976834 | E11: 炽灼·决断 | F11: =IFERROR(VLOOKUP($E11,角色MOD表[],MATCH(F$6,角色MOD表[#Headers],0),0),"") -> 契约者 | G11: =IFERROR(VLOOKUP($E11,角色MOD表[],MATCH(G$6,角色MOD表[#Headers],0),0),"") -> 金 | H11: =IFERROR(VLOOKUP($E11,角色MOD表[],MATCH(H$6,角色MOD表[#Headers],0),0),"")&"" -> V | I11: =IF(AND(K11<>"",H11<>""),ROUNDUP(IF(H11=K11,IFERROR(VLOOKUP($E11,角色MOD表[],6,0)+$J11-IF($G11="金",10,IF($G11="绿",3,5)),0)/2,IFERROR(VLOOKUP($E11,角色MOD表[],6,0)+$J11-IF($G11="金",10,IF($G11="绿",3,5)),0)*1.5),0),IFERROR(VLOOKUP($E11,角色MOD表[],6,0)+$J11-IF($G11="金",10,IF($G11="绿",3,5)),0)) -> 20 | J11: 10 | L11: {=IFERROR(INDEX(角色MOD表[#Headers],SMALL(_xlfn._xlws.FILTER(COLUMN(_xlfn.DROP(INDEX(角色MOD表[],MATCH($E11,角色MOD表[名称],0),),,MATCH("耐受",角色MOD表[#Headers],0)))*(_xlfn.DROP(INDEX(角色MOD表[],MATCH($E11,角色MOD表[名称],0),),,6)<>""),COLUMN(_xlfn.DROP(INDEX(角色MOD表[],MATCH($E11,角色MOD表[名称],0),),,MATCH("耐受",角色MOD表[#Headers],0)))*(_xlfn.DROP(INDEX(角色MOD表[],MATCH($E11,角色MOD表[名称],0),),,6)<>"")<>0),ROUNDUP(COLUMNS($L11:L11)/2,0))),"")} -> 威力 | M11: {=IFERROR(_xlfn.MAP(INDEX(INDEX(角色MOD表[],MATCH($E11,角色MOD表[名称],0),),SMALL(_xlfn._xlws.FILTER(COLUMN(_xlfn.DROP(INDEX(角色MOD表[],MATCH($E11,角色MOD表[名称],0),),,MATCH("耐受",角色MOD表[#Headers],0)))*(_xlfn.DROP(INDEX(角色MOD表[],MATCH($E11,角色MOD表[名称],0),),,MATCH("耐受",角色MOD表[#Headers],0))<>""),COLUMN(_xlfn.DROP(INDEX(角色MOD表[],MATCH($E11,角色MOD表[名称],0),),,MATCH("耐受",角色MOD表[#Headers],0)))*(_xlfn.DROP(INDEX(角色MOD表[],MATCH($E11,角色MOD表[名称],0),),,MATCH("耐受",角色MOD表[#Headers],0))<>"")<>0),ROUNDUP(COLUMNS($L11:L11)/2,0))),_xlfn.LAMBDA(_xlpm.x,IFERROR(IF(ISNUMBER(MATCH($F11,{"百首","狮鹫","契约者"},0)),1+SUM(IFERROR(BUFF层数乘数*VLOOKUP(BUFF,BUFF表[],MATCH("MOD属性",BUFF表[#Headers],0),0),0)),1)*MIN(1,($J11+1)/IF($G11="金",11,IF($G11="绿",4,6)))*_xlpm.x,_xlpm.x))),"")} -> 0.44792 | N11: {=IFERROR(INDEX(角色MOD表[#Headers],SMALL(_xlfn._xlws.FILTER(COLUMN(_xlfn.DROP(INDEX(角色MOD表[],MATCH($E11,角色MOD表[名称],0),),,MATCH("耐受",角色MOD表[#Headers],0)))*(_xlfn.DROP(INDEX(角色MOD表[],MATCH($E11,角色MOD表[名称],0),),,6)<>""),COLUMN(_xlfn.DROP(INDEX(角色MOD表[],MATCH($E11,角色MOD表[名称],0),),,MATCH("耐受",角色MOD表[#Headers],0)))*(_xlfn.DROP(INDEX(角色MOD表[],MATCH($E11,角色MOD表[名称],0),),,6)<>"")<>0),ROUNDUP(COLUMNS($L11:N11)/2,0))),"")} -> 攻击 | O11: {=IFERROR(_xlfn.MAP(INDEX(INDEX(角色MOD表[],MATCH($E11,角色MOD表[名称],0),),SMALL(_xlfn._xlws.FILTER(COLUMN(_xlfn.DROP(INDEX(角色MOD表[],MATCH($E11,角色MOD表[名称],0),),,MATCH("耐受",角色MOD表[#Headers],0)))*(_xlfn.DROP(INDEX(角色MOD表[],MATCH($E11,角色MOD表[名称],0),),,MATCH("耐受",角色MOD表[#Headers],0))<>""),COLUMN(_xlfn.DROP(INDEX(角色MOD表[],MATCH($E11,角色MOD表[名称],0),),,MATCH("耐受",角色MOD表[#Headers],0)))*(_xlfn.DROP(INDEX(角色MOD表[],MATCH($E11,角色MOD表[名称],0),),,MATCH("耐受",角色MOD表[#Headers],0))<>"")<>0),ROUNDUP(COLUMNS($L11:N11)/2,0))),_xlfn.LAMBDA(_xlpm.x,IFERROR(IF(ISNUMBER(MATCH($F11,{"百首","狮鹫","契约者"},0)),1+SUM(IFERROR(BUFF层数乘数*VLOOKUP(BUFF,BUFF表[],MATCH("MOD属性",BUFF表[#Headers],0),0),0)),1)*MIN(1,($J11+1)/IF($G11="金",11,IF($G11="绿",4,6)))*_xlpm.x,_xlpm.x))),"")} -> 0.89584 | P11: {=IFERROR(INDEX(角色MOD表[#Headers],SMALL(_xlfn._xlws.FILTER(COLUMN(_xlfn.DROP(INDEX(角色MOD表[],MATCH($E11,角色MOD表[名称],0),),,MATCH("耐受",角色MOD表[#Headers],0)))*(_xlfn.DROP(INDEX(角色MOD表[],MATCH($E11,角色MOD表[名称],0),),,6)<>""),COLUMN(_xlfn.DROP(INDEX(角色MOD表[],MATCH($E11,角色MOD表[名称],0),),,MATCH("耐受",角色MOD表[#Headers],0)))*(_xlfn.DROP(INDEX(角色MOD表[],MATCH($E11,角色MOD表[名称],0),),,6)<>"")<>0),ROUNDUP(COLUMNS($L11:P11)/2,0))),"")} | Q11: {=IFERROR(_xlfn.MAP(INDEX(INDEX(角色MOD表[],MATCH($E11,角色MOD表[名称],0),),SMALL(_xlfn._xlws.FILTER(COLUMN(_xlfn.DROP(INDEX(角色MOD表[],MATCH($E11,角色MOD表[名称],0),),,MATCH("耐受",角色MOD表[#Headers],0)))*(_xlfn.DROP(INDEX(角色MOD表[],MATCH($E11,角色MOD表[名称],0),),,MATCH("耐受",角色MOD表[#Headers],0))<>""),COLUMN(_xlfn.DROP(INDEX(角色MOD表[],MATCH($E11,角色MOD表[名称],0),),,MATCH("耐受",角色MOD表[#Headers],0)))*(_xlfn.DROP(INDEX(角色MOD表[],MATCH($E11,角色MOD表[名称],0),),,MATCH("耐受",角色MOD表[#Headers],0))<>"")<>0),ROUNDUP(COLUMNS($L11:P11)/2,0))),_xlfn.LAMBDA(_xlpm.x,IFERROR(IF(ISNUMBER(MATCH($F11,{"百首","狮鹫","契约者"},0)),1+SUM(IFERROR(BUFF层数乘数*VLOOKUP(BUFF,BUFF表[],MATCH("MOD属性",BUFF表[#Headers],0),0),0)),1)*MIN(1,($J11+1)/IF($G11="金",11,IF($G11="绿",4,6)))*_xlpm.x,_xlpm.x))),"")} | R11: {=IFERROR(INDEX(角色MOD表[#Headers],SMALL(_xlfn._xlws.FILTER(COLUMN(_xlfn.DROP(INDEX(角色MOD表[],MATCH($E11,角色MOD表[名称],0),),,MATCH("耐受",角色MOD表[#Headers],0)))*(_xlfn.DROP(INDEX(角色MOD表[],MATCH($E11,角色MOD表[名称],0),),,6)<>""),COLUMN(_xlfn.DROP(INDEX(角色MOD表[],MATCH($E11,角色MOD表[名称],0),),,MATCH("耐受",角色MOD表[#Headers],0)))*(_xlfn.DROP(INDEX(角色MOD表[],MATCH($E11,角色MOD表[名称],0),),,6)<>"")<>0),ROUNDUP(COLUMNS($L11:R11)/2,0))),"")} | S11: {=IFERROR(_xlfn.MAP(INDEX(INDEX(角色MOD表[],MATCH($E11,角色MOD表[名称],0),),SMALL(_xlfn._xlws.FILTER(COLUMN(_xlfn.DROP(INDEX(角色MOD表[],MATCH($E11,角色MOD表[名称],0),),,MATCH("耐受",角色MOD表[#Headers],0)))*(_xlfn.DROP(INDEX(角色MOD表[],MATCH($E11,角色MOD表[名称],0),),,MATCH("耐受",角色MOD表[#Headers],0))<>""),COLUMN(_xlfn.DROP(INDEX(角色MOD表[],MATCH($E11,角色MOD表[名称],0),),,MATCH("耐受",角色MOD表[#Headers],0)))*(_xlfn.DROP(INDEX(角色MOD表[],MATCH($E11,角色MOD表[名称],0),),,MATCH("耐受",角色MOD表[#Headers],0))<>"")<>0),ROUNDUP(COLUMNS($L11:R11)/2,0))),_xlfn.LAMBDA(_xlpm.x,IFERROR(IF(ISNUMBER(MATCH($F11,{"百首","狮鹫","契约者"},0)),1+SUM(IFERROR(BUFF层数乘数*VLOOKUP(BUFF,BUFF表[],MATCH("MOD属性",BUFF表[#Headers],0),0),0)),1)*MIN(1,($J11+1)/IF($G11="金",11,IF($G11="绿",4,6)))*_xlpm.x,_xlpm.x))),"")} | T11: {=X11*SUM(B$24*U11,B$26*V11,B$25*W11,B$27)*昂扬背水乘区(AB11,AC11)*SUM(1,AD11,AE11)*(1-敌方抗性+AF11)*(1+AG11)/IF($A$39="DPMP",ROUNDUP($B$30*(2-Z11),0),1)/IF($A$39="DPSMP",ROUNDUP($B$31*MAX(0.25,(2-Z11)/Y11),0),1)*防御乘区(AH11)} -> 768463.32 | U11: {=删MOD取角色属性(U$6,ROWS($J$7:$J11))*(1+删MOD取角色属性("属性伤",ROWS($J$7:$J11)))} -> 5616.3875 | V11: {=删MOD取角色属性(V$6,ROWS($J$7:$J11))} -> 3388.6505 | W11: {=删MOD取角色属性(W$6,ROWS($J$7:$J11))} -> 971.49024 | X11: {=删MOD取角色属性(X$6,ROWS($J$7:$J11))} -> 7.56762 | Y11: {=删MOD取角色属性(Y$6,ROWS($J$7:$J11))} -> 1.2 | Z11: {=删MOD取角色属性(Z$6,ROWS($J$7:$J11))} -> 0 | AA11: {=删MOD取角色属性(AA$6,ROWS($J$7:$J11))} -> 1.33594 | AB11: {=删MOD取角色属性(AB$6,ROWS($J$7:$J11))} -> 0 | AC11: {=删MOD取角色属性(AC$6,ROWS($J$7:$J11))} -> 0.83008 | ... AH11: {=删MOD取角色属性(AH$6,ROWS($J$7:$J11))} -> 0 | AV11: 全盛·追袭 | AW11: 瞬袭 | AX11: 箭雨 | BJ11: 10 | BK11: 11 | BM11: 10 | BN11: 11 | BT11: 10 | BU11: 10 | BV11: 10 | BX11: 10
A12: 威力 | B12: =1+IFERROR(VLOOKUP($B$3,角色表[],MATCH(A12,角色表[#Headers],0),0),0) -> 1.2 | C12: {=取角色总属性(A12)} -> 8.01554 | D12: =(B$39-T12)/T12 -> 0.14976834 | E12: 炽灼·决断 | F12: =IFERROR(VLOOKUP($E12,角色MOD表[],MATCH(F$6,角色MOD表[#Headers],0),0),"") -> 契约者 | G12: =IFERROR(VLOOKUP($E12,角色MOD表[],MATCH(G$6,角色MOD表[#Headers],0),0),"") -> 金 | H12: =IFERROR(VLOOKUP($E12,角色MOD表[],MATCH(H$6,角色MOD表[#Headers],0),0),"")&"" -> V | I12: =IF(AND(K12<>"",H12<>""),ROUNDUP(IF(H12=K12,IFERROR(VLOOKUP($E12,角色MOD表[],6,0)+$J12-IF($G12="金",10,IF($G12="绿",3,5)),0)/2,IFERROR(VLOOKUP($E12,角色MOD表[],6,0)+$J12-IF($G12="金",10,IF($G12="绿",3,5)),0)*1.5),0),IFERROR(VLOOKUP($E12,角色MOD表[],6,0)+$J12-IF($G12="金",10,IF($G12="绿",3,5)),0)) -> 20 | J12: 10 | L12: {=IFERROR(INDEX(角色MOD表[#Headers],SMALL(_xlfn._xlws.FILTER(COLUMN(_xlfn.DROP(INDEX(角色MOD表[],MATCH($E12,角色MOD表[名称],0),),,MATCH("耐受",角色MOD表[#Headers],0)))*(_xlfn.DROP(INDEX(角色MOD表[],MATCH($E12,角色MOD表[名称],0),),,6)<>""),COLUMN(_xlfn.DROP(INDEX(角色MOD表[],MATCH($E12,角色MOD表[名称],0),),,MATCH("耐受",角色MOD表[#Headers],0)))*(_xlfn.DROP(INDEX(角色MOD表[],MATCH($E12,角色MOD表[名称],0),),,6)<>"")<>0),ROUNDUP(COLUMNS($L12:L12)/2,0))),"")} -> 威力 | M12: {=IFERROR(_xlfn.MAP(INDEX(INDEX(角色MOD表[],MATCH($E12,角色MOD表[名称],0),),SMALL(_xlfn._xlws.FILTER(COLUMN(_xlfn.DROP(INDEX(角色MOD表[],MATCH($E12,角色MOD表[名称],0),),,MATCH("耐受",角色MOD表[#Headers],0)))*(_xlfn.DROP(INDEX(角色MOD表[],MATCH($E12,角色MOD表[名称],0),),,MATCH("耐受",角色MOD表[#Headers],0))<>""),COLUMN(_xlfn.DROP(INDEX(角色MOD表[],MATCH($E12,角色MOD表[名称],0),),,MATCH("耐受",角色MOD表[#Headers],0)))*(_xlfn.DROP(INDEX(角色MOD表[],MATCH($E12,角色MOD表[名称],0),),,MATCH("耐受",角色MOD表[#Headers],0))<>"")<>0),ROUNDUP(COLUMNS($L12:L12)/2,0))),_xlfn.LAMBDA(_xlpm.x,IFERROR(IF(ISNUMBER(MATCH($F12,{"百首","狮鹫","契约者"},0)),1+SUM(IFERROR(BUFF层数乘数*VLOOKUP(BUFF,BUFF表[],MATCH("MOD属性",BUFF表[#Headers],0),0),0)),1)*MIN(1,($J12+1)/IF($G12="金",11,IF($G12="绿",4,6)))*_xlpm.x,_xlpm.x))),"")} -> 0.44792 | N12: {=IFERROR(INDEX(角色MOD表[#Headers],SMALL(_xlfn._xlws.FILTER(COLUMN(_xlfn.DROP(INDEX(角色MOD表[],MATCH($E12,角色MOD表[名称],0),),,MATCH("耐受",角色MOD表[#Headers],0)))*(_xlfn.DROP(INDEX(角色MOD表[],MATCH($E12,角色MOD表[名称],0),),,6)<>""),COLUMN(_xlfn.DROP(INDEX(角色MOD表[],MATCH($E12,角色MOD表[名称],0),),,MATCH("耐受",角色MOD表[#Headers],0)))*(_xlfn.DROP(INDEX(角色MOD表[],MATCH($E12,角色MOD表[名称],0),),,6)<>"")<>0),ROUNDUP(COLUMNS($L12:N12)/2,0))),"")} -> 攻击 | O12: {=IFERROR(_xlfn.MAP(INDEX(INDEX(角色MOD表[],MATCH($E12,角色MOD表[名称],0),),SMALL(_xlfn._xlws.FILTER(COLUMN(_xlfn.DROP(INDEX(角色MOD表[],MATCH($E12,角色MOD表[名称],0),),,MATCH("耐受",角色MOD表[#Headers],0)))*(_xlfn.DROP(INDEX(角色MOD表[],MATCH($E12,角色MOD表[名称],0),),,MATCH("耐受",角色MOD表[#Headers],0))<>""),COLUMN(_xlfn.DROP(INDEX(角色MOD表[],MATCH($E12,角色MOD表[名称],0),),,MATCH("耐受",角色MOD表[#Headers],0)))*(_xlfn.DROP(INDEX(角色MOD表[],MATCH($E12,角色MOD表[名称],0),),,MATCH("耐受",角色MOD表[#Headers],0))<>"")<>0),ROUNDUP(COLUMNS($L12:N12)/2,0))),_xlfn.LAMBDA(_xlpm.x,IFERROR(IF(ISNUMBER(MATCH($F12,{"百首","狮鹫","契约者"},0)),1+SUM(IFERROR(BUFF层数乘数*VLOOKUP(BUFF,BUFF表[],MATCH("MOD属性",BUFF表[#Headers],0),0),0)),1)*MIN(1,($J12+1)/IF($G12="金",11,IF($G12="绿",4,6)))*_xlpm.x,_xlpm.x))),"")} -> 0.89584 | P12: {=IFERROR(INDEX(角色MOD表[#Headers],SMALL(_xlfn._xlws.FILTER(COLUMN(_xlfn.DROP(INDEX(角色MOD表[],MATCH($E12,角色MOD表[名称],0),),,MATCH("耐受",角色MOD表[#Headers],0)))*(_xlfn.DROP(INDEX(角色MOD表[],MATCH($E12,角色MOD表[名称],0),),,6)<>""),COLUMN(_xlfn.DROP(INDEX(角色MOD表[],MATCH($E12,角色MOD表[名称],0),),,MATCH("耐受",角色MOD表[#Headers],0)))*(_xlfn.DROP(INDEX(角色MOD表[],MATCH($E12,角色MOD表[名称],0),),,6)<>"")<>0),ROUNDUP(COLUMNS($L12:P12)/2,0))),"")} | Q12: {=IFERROR(_xlfn.MAP(INDEX(INDEX(角色MOD表[],MATCH($E12,角色MOD表[名称],0),),SMALL(_xlfn._xlws.FILTER(COLUMN(_xlfn.DROP(INDEX(角色MOD表[],MATCH($E12,角色MOD表[名称],0),),,MATCH("耐受",角色MOD表[#Headers],0)))*(_xlfn.DROP(INDEX(角色MOD表[],MATCH($E12,角色MOD表[名称],0),),,MATCH("耐受",角色MOD表[#Headers],0))<>""),COLUMN(_xlfn.DROP(INDEX(角色MOD表[],MATCH($E12,角色MOD表[名称],0),),,MATCH("耐受",角色MOD表[#Headers],0)))*(_xlfn.DROP(INDEX(角色MOD表[],MATCH($E12,角色MOD表[名称],0),),,MATCH("耐受",角色MOD表[#Headers],0))<>"")<>0),ROUNDUP(COLUMNS($L12:P12)/2,0))),_xlfn.LAMBDA(_xlpm.x,IFERROR(IF(ISNUMBER(MATCH($F12,{"百首","狮鹫","契约者"},0)),1+SUM(IFERROR(BUFF层数乘数*VLOOKUP(BUFF,BUFF表[],MATCH("MOD属性",BUFF表[#Headers],0),0),0)),1)*MIN(1,($J12+1)/IF($G12="金",11,IF($G12="绿",4,6)))*_xlpm.x,_xlpm.x))),"")} | R12: {=IFERROR(INDEX(角色MOD表[#Headers],SMALL(_xlfn._xlws.FILTER(COLUMN(_xlfn.DROP(INDEX(角色MOD表[],MATCH($E12,角色MOD表[名称],0),),,MATCH("耐受",角色MOD表[#Headers],0)))*(_xlfn.DROP(INDEX(角色MOD表[],MATCH($E12,角色MOD表[名称],0),),,6)<>""),COLUMN(_xlfn.DROP(INDEX(角色MOD表[],MATCH($E12,角色MOD表[名称],0),),,MATCH("耐受",角色MOD表[#Headers],0)))*(_xlfn.DROP(INDEX(角色MOD表[],MATCH($E12,角色MOD表[名称],0),),,6)<>"")<>0),ROUNDUP(COLUMNS($L12:R12)/2,0))),"")} | S12: {=IFERROR(_xlfn.MAP(INDEX(INDEX(角色MOD表[],MATCH($E12,角色MOD表[名称],0),),SMALL(_xlfn._xlws.FILTER(COLUMN(_xlfn.DROP(INDEX(角色MOD表[],MATCH($E12,角色MOD表[名称],0),),,MATCH("耐受",角色MOD表[#Headers],0)))*(_xlfn.DROP(INDEX(角色MOD表[],MATCH($E12,角色MOD表[名称],0),),,MATCH("耐受",角色MOD表[#Headers],0))<>""),COLUMN(_xlfn.DROP(INDEX(角色MOD表[],MATCH($E12,角色MOD表[名称],0),),,MATCH("耐受",角色MOD表[#Headers],0)))*(_xlfn.DROP(INDEX(角色MOD表[],MATCH($E12,角色MOD表[名称],0),),,MATCH("耐受",角色MOD表[#Headers],0))<>"")<>0),ROUNDUP(COLUMNS($L12:R12)/2,0))),_xlfn.LAMBDA(_xlpm.x,IFERROR(IF(ISNUMBER(MATCH($F12,{"百首","狮鹫","契约者"},0)),1+SUM(IFERROR(BUFF层数乘数*VLOOKUP(BUFF,BUFF表[],MATCH("MOD属性",BUFF表[#Headers],0),0),0)),1)*MIN(1,($J12+1)/IF($G12="金",11,IF($G12="绿",4,6)))*_xlpm.x,_xlpm.x))),"")} | T12: {=X12*SUM(B$24*U12,B$26*V12,B$25*W12,B$27)*昂扬背水乘区(AB12,AC12)*SUM(1,AD12,AE12)*(1-敌方抗性+AF12)*(1+AG12)/IF($A$39="DPMP",ROUNDUP($B$30*(2-Z12),0),1)/IF($A$39="DPSMP",ROUNDUP($B$31*MAX(0.25,(2-Z12)/Y12),0),1)*防御乘区(AH12)} -> 768463.32 | U12: {=删MOD取角色属性(U$6,ROWS($J$7:$J12))*(1+删MOD取角色属性("属性伤",ROWS($J$7:$J12)))} -> 5616.3875 | V12: {=删MOD取角色属性(V$6,ROWS($J$7:$J12))} -> 3388.6505 | W12: {=删MOD取角色属性(W$6,ROWS($J$7:$J12))} -> 971.49024 | X12: {=删MOD取角色属性(X$6,ROWS($J$7:$J12))} -> 7.56762 | Y12: {=删MOD取角色属性(Y$6,ROWS($J$7:$J12))} -> 1.2 | Z12: {=删MOD取角色属性(Z$6,ROWS($J$7:$J12))} -> 0 | AA12: {=删MOD取角色属性(AA$6,ROWS($J$7:$J12))} -> 1.33594 | AB12: {=删MOD取角色属性(AB$6,ROWS($J$7:$J12))} -> 0 | AC12: {=删MOD取角色属性(AC$6,ROWS($J$7:$J12))} -> 0.83008 | ... AH12: {=删MOD取角色属性(AH$6,ROWS($J$7:$J12))} -> 0 | AV12: 全盛·安神 | AW12: 坠击 | AX12: 箭匣·整备 | BK12: 12 | BN12: 12
A13: 耐久 | B13: =1+IFERROR(VLOOKUP($B$3,角色表[],MATCH(A13,角色表[#Headers],0),0),0) -> 1 | C13: {=取角色总属性(A13)} -> 1.2 | D13: =(B$39-T13)/T13 -> 0.14976834 | E13: 炽灼·决断 | F13: =IFERROR(VLOOKUP($E13,角色MOD表[],MATCH(F$6,角色MOD表[#Headers],0),0),"") -> 契约者 | G13: =IFERROR(VLOOKUP($E13,角色MOD表[],MATCH(G$6,角色MOD表[#Headers],0),0),"") -> 金 | H13: =IFERROR(VLOOKUP($E13,角色MOD表[],MATCH(H$6,角色MOD表[#Headers],0),0),"")&"" -> V | I13: =IF(AND(K13<>"",H13<>""),ROUNDUP(IF(H13=K13,IFERROR(VLOOKUP($E13,角色MOD表[],6,0)+$J13-IF($G13="金",10,IF($G13="绿",3,5)),0)/2,IFERROR(VLOOKUP($E13,角色MOD表[],6,0)+$J13-IF($G13="金",10,IF($G13="绿",3,5)),0)*1.5),0),IFERROR(VLOOKUP($E13,角色MOD表[],6,0)+$J13-IF($G13="金",10,IF($G13="绿",3,5)),0)) -> 20 | J13: 10 | L13: {=IFERROR(INDEX(角色MOD表[#Headers],SMALL(_xlfn._xlws.FILTER(COLUMN(_xlfn.DROP(INDEX(角色MOD表[],MATCH($E13,角色MOD表[名称],0),),,MATCH("耐受",角色MOD表[#Headers],0)))*(_xlfn.DROP(INDEX(角色MOD表[],MATCH($E13,角色MOD表[名称],0),),,6)<>""),COLUMN(_xlfn.DROP(INDEX(角色MOD表[],MATCH($E13,角色MOD表[名称],0),),,MATCH("耐受",角色MOD表[#Headers],0)))*(_xlfn.DROP(INDEX(角色MOD表[],MATCH($E13,角色MOD表[名称],0),),,6)<>"")<>0),ROUNDUP(COLUMNS($L13:L13)/2,0))),"")} -> 威力 | M13: {=IFERROR(_xlfn.MAP(INDEX(INDEX(角色MOD表[],MATCH($E13,角色MOD表[名称],0),),SMALL(_xlfn._xlws.FILTER(COLUMN(_xlfn.DROP(INDEX(角色MOD表[],MATCH($E13,角色MOD表[名称],0),),,MATCH("耐受",角色MOD表[#Headers],0)))*(_xlfn.DROP(INDEX(角色MOD表[],MATCH($E13,角色MOD表[名称],0),),,MATCH("耐受",角色MOD表[#Headers],0))<>""),COLUMN(_xlfn.DROP(INDEX(角色MOD表[],MATCH($E13,角色MOD表[名称],0),),,MATCH("耐受",角色MOD表[#Headers],0)))*(_xlfn.DROP(INDEX(角色MOD表[],MATCH($E13,角色MOD表[名称],0),),,MATCH("耐受",角色MOD表[#Headers],0))<>"")<>0),ROUNDUP(COLUMNS($L13:L13)/2,0))),_xlfn.LAMBDA(_xlpm.x,IFERROR(IF(ISNUMBER(MATCH($F13,{"百首","狮鹫","契约者"},0)),1+SUM(IFERROR(BUFF层数乘数*VLOOKUP(BUFF,BUFF表[],MATCH("MOD属性",BUFF表[#Headers],0),0),0)),1)*MIN(1,($J13+1)/IF($G13="金",11,IF($G13="绿",4,6)))*_xlpm.x,_xlpm.x))),"")} -> 0.44792 | N13: {=IFERROR(INDEX(角色MOD表[#Headers],SMALL(_xlfn._xlws.FILTER(COLUMN(_xlfn.DROP(INDEX(角色MOD表[],MATCH($E13,角色MOD表[名称],0),),,MATCH("耐受",角色MOD表[#Headers],0)))*(_xlfn.DROP(INDEX(角色MOD表[],MATCH($E13,角色MOD表[名称],0),),,6)<>""),COLUMN(_xlfn.DROP(INDEX(角色MOD表[],MATCH($E13,角色MOD表[名称],0),),,MATCH("耐受",角色MOD表[#Headers],0)))*(_xlfn.DROP(INDEX(角色MOD表[],MATCH($E13,角色MOD表[名称],0),),,6)<>"")<>0),ROUNDUP(COLUMNS($L13:N13)/2,0))),"")} -> 攻击 | O13: {=IFERROR(_xlfn.MAP(INDEX(INDEX(角色MOD表[],MATCH($E13,角色MOD表[名称],0),),SMALL(_xlfn._xlws.FILTER(COLUMN(_xlfn.DROP(INDEX(角色MOD表[],MATCH($E13,角色MOD表[名称],0),),,MATCH("耐受",角色MOD表[#Headers],0)))*(_xlfn.DROP(INDEX(角色MOD表[],MATCH($E13,角色MOD表[名称],0),),,MATCH("耐受",角色MOD表[#Headers],0))<>""),COLUMN(_xlfn.DROP(INDEX(角色MOD表[],MATCH($E13,角色MOD表[名称],0),),,MATCH("耐受",角色MOD表[#Headers],0)))*(_xlfn.DROP(INDEX(角色MOD表[],MATCH($E13,角色MOD表[名称],0),),,MATCH("耐受",角色MOD表[#Headers],0))<>"")<>0),ROUNDUP(COLUMNS($L13:N13)/2,0))),_xlfn.LAMBDA(_xlpm.x,IFERROR(IF(ISNUMBER(MATCH($F13,{"百首","狮鹫","契约者"},0)),1+SUM(IFERROR(BUFF层数乘数*VLOOKUP(BUFF,BUFF表[],MATCH("MOD属性",BUFF表[#Headers],0),0),0)),1)*MIN(1,($J13+1)/IF($G13="金",11,IF($G13="绿",4,6)))*_xlpm.x,_xlpm.x))),"")} -> 0.89584 | P13: {=IFERROR(INDEX(角色MOD表[#Headers],SMALL(_xlfn._xlws.FILTER(COLUMN(_xlfn.DROP(INDEX(角色MOD表[],MATCH($E13,角色MOD表[名称],0),),,MATCH("耐受",角色MOD表[#Headers],0)))*(_xlfn.DROP(INDEX(角色MOD表[],MATCH($E13,角色MOD表[名称],0),),,6)<>""),COLUMN(_xlfn.DROP(INDEX(角色MOD表[],MATCH($E13,角色MOD表[名称],0),),,MATCH("耐受",角色MOD表[#Headers],0)))*(_xlfn.DROP(INDEX(角色MOD表[],MATCH($E13,角色MOD表[名称],0),),,6)<>"")<>0),ROUNDUP(COLUMNS($L13:P13)/2,0))),"")} | Q13: {=IFERROR(_xlfn.MAP(INDEX(INDEX(角色MOD表[],MATCH($E13,角色MOD表[名称],0),),SMALL(_xlfn._xlws.FILTER(COLUMN(_xlfn.DROP(INDEX(角色MOD表[],MATCH($E13,角色MOD表[名称],0),),,MATCH("耐受",角色MOD表[#Headers],0)))*(_xlfn.DROP(INDEX(角色MOD表[],MATCH($E13,角色MOD表[名称],0),),,MATCH("耐受",角色MOD表[#Headers],0))<>""),COLUMN(_xlfn.DROP(INDEX(角色MOD表[],MATCH($E13,角色MOD表[名称],0),),,MATCH("耐受",角色MOD表[#Headers],0)))*(_xlfn.DROP(INDEX(角色MOD表[],MATCH($E13,角色MOD表[名称],0),),,MATCH("耐受",角色MOD表[#Headers],0))<>"")<>0),ROUNDUP(COLUMNS($L13:P13)/2,0))),_xlfn.LAMBDA(_xlpm.x,IFERROR(IF(ISNUMBER(MATCH($F13,{"百首","狮鹫","契约者"},0)),1+SUM(IFERROR(BUFF层数乘数*VLOOKUP(BUFF,BUFF表[],MATCH("MOD属性",BUFF表[#Headers],0),0),0)),1)*MIN(1,($J13+1)/IF($G13="金",11,IF($G13="绿",4,6)))*_xlpm.x,_xlpm.x))),"")} | R13: {=IFERROR(INDEX(角色MOD表[#Headers],SMALL(_xlfn._xlws.FILTER(COLUMN(_xlfn.DROP(INDEX(角色MOD表[],MATCH($E13,角色MOD表[名称],0),),,MATCH("耐受",角色MOD表[#Headers],0)))*(_xlfn.DROP(INDEX(角色MOD表[],MATCH($E13,角色MOD表[名称],0),),,6)<>""),COLUMN(_xlfn.DROP(INDEX(角色MOD表[],MATCH($E13,角色MOD表[名称],0),),,MATCH("耐受",角色MOD表[#Headers],0)))*(_xlfn.DROP(INDEX(角色MOD表[],MATCH($E13,角色MOD表[名称],0),),,6)<>"")<>0),ROUNDUP(COLUMNS($L13:R13)/2,0))),"")} | S13: {=IFERROR(_xlfn.MAP(INDEX(INDEX(角色MOD表[],MATCH($E13,角色MOD表[名称],0),),SMALL(_xlfn._xlws.FILTER(COLUMN(_xlfn.DROP(INDEX(角色MOD表[],MATCH($E13,角色MOD表[名称],0),),,MATCH("耐受",角色MOD表[#Headers],0)))*(_xlfn.DROP(INDEX(角色MOD表[],MATCH($E13,角色MOD表[名称],0),),,MATCH("耐受",角色MOD表[#Headers],0))<>""),COLUMN(_xlfn.DROP(INDEX(角色MOD表[],MATCH($E13,角色MOD表[名称],0),),,MATCH("耐受",角色MOD表[#Headers],0)))*(_xlfn.DROP(INDEX(角色MOD表[],MATCH($E13,角色MOD表[名称],0),),,MATCH("耐受",角色MOD表[#Headers],0))<>"")<>0),ROUNDUP(COLUMNS($L13:R13)/2,0))),_xlfn.LAMBDA(_xlpm.x,IFERROR(IF(ISNUMBER(MATCH($F13,{"百首","狮鹫","契约者"},0)),1+SUM(IFERROR(BUFF层数乘数*VLOOKUP(BUFF,BUFF表[],MATCH("MOD属性",BUFF表[#Headers],0),0),0)),1)*MIN(1,($J13+1)/IF($G13="金",11,IF($G13="绿",4,6)))*_xlpm.x,_xlpm.x))),"")} | T13: {=X13*SUM(B$24*U13,B$26*V13,B$25*W13,B$27)*昂扬背水乘区(AB13,AC13)*SUM(1,AD13,AE13)*(1-敌方抗性+AF13)*(1+AG13)/IF($A$39="DPMP",ROUNDUP($B$30*(2-Z13),0),1)/IF($A$39="DPSMP",ROUNDUP($B$31*MAX(0.25,(2-Z13)/Y13),0),1)*防御乘区(AH13)} -> 768463.32 | U13: {=删MOD取角色属性(U$6,ROWS($J$7:$J13))*(1+删MOD取角色属性("属性伤",ROWS($J$7:$J13)))} -> 5616.3875 | V13: {=删MOD取角色属性(V$6,ROWS($J$7:$J13))} -> 3388.6505 | W13: {=删MOD取角色属性(W$6,ROWS($J$7:$J13))} -> 971.49024 | X13: {=删MOD取角色属性(X$6,ROWS($J$7:$J13))} -> 7.56762 | Y13: {=删MOD取角色属性(Y$6,ROWS($J$7:$J13))} -> 1.2 | Z13: {=删MOD取角色属性(Z$6,ROWS($J$7:$J13))} -> 0 | AA13: {=删MOD取角色属性(AA$6,ROWS($J$7:$J13))} -> 1.33594 | AB13: {=删MOD取角色属性(AB$6,ROWS($J$7:$J13))} -> 0 | AC13: {=删MOD取角色属性(AC$6,ROWS($J$7:$J13))} -> 0.83008 | ... AH13: {=删MOD取角色属性(AH$6,ROWS($J$7:$J13))} -> 0 | AV13: 全盛·振奋 | AW13: 迅捷坠击 | AX13: 重压·箭匣
A14: 效益 | B14: =1+IFERROR(VLOOKUP($B$3,角色表[],MATCH(A14,角色表[#Headers],0),0),0) -> 1 | C14: {=取角色总属性(A14)} -> 0 | D14: =(B$39-T14)/T14 -> 0.14976834 | E14: 炽灼·决断 | F14: =IFERROR(VLOOKUP($E14,角色MOD表[],MATCH(F$6,角色MOD表[#Headers],0),0),"") -> 契约者 | G14: =IFERROR(VLOOKUP($E14,角色MOD表[],MATCH(G$6,角色MOD表[#Headers],0),0),"") -> 金 | H14: =IFERROR(VLOOKUP($E14,角色MOD表[],MATCH(H$6,角色MOD表[#Headers],0),0),"")&"" -> V | I14: =IF(AND(K14<>"",H14<>""),ROUNDUP(IF(H14=K14,IFERROR(VLOOKUP($E14,角色MOD表[],6,0)+$J14-IF($G14="金",10,IF($G14="绿",3,5)),0)/2,IFERROR(VLOOKUP($E14,角色MOD表[],6,0)+$J14-IF($G14="金",10,IF($G14="绿",3,5)),0)*1.5),0),IFERROR(VLOOKUP($E14,角色MOD表[],6,0)+$J14-IF($G14="金",10,IF($G14="绿",3,5)),0)) -> 20 | J14: 10 | L14: {=IFERROR(INDEX(角色MOD表[#Headers],SMALL(_xlfn._xlws.FILTER(COLUMN(_xlfn.DROP(INDEX(角色MOD表[],MATCH($E14,角色MOD表[名称],0),),,MATCH("耐受",角色MOD表[#Headers],0)))*(_xlfn.DROP(INDEX(角色MOD表[],MATCH($E14,角色MOD表[名称],0),),,6)<>""),COLUMN(_xlfn.DROP(INDEX(角色MOD表[],MATCH($E14,角色MOD表[名称],0),),,MATCH("耐受",角色MOD表[#Headers],0)))*(_xlfn.DROP(INDEX(角色MOD表[],MATCH($E14,角色MOD表[名称],0),),,6)<>"")<>0),ROUNDUP(COLUMNS($L14:L14)/2,0))),"")} -> 威力 | M14: {=IFERROR(_xlfn.MAP(INDEX(INDEX(角色MOD表[],MATCH($E14,角色MOD表[名称],0),),SMALL(_xlfn._xlws.FILTER(COLUMN(_xlfn.DROP(INDEX(角色MOD表[],MATCH($E14,角色MOD表[名称],0),),,MATCH("耐受",角色MOD表[#Headers],0)))*(_xlfn.DROP(INDEX(角色MOD表[],MATCH($E14,角色MOD表[名称],0),),,MATCH("耐受",角色MOD表[#Headers],0))<>""),COLUMN(_xlfn.DROP(INDEX(角色MOD表[],MATCH($E14,角色MOD表[名称],0),),,MATCH("耐受",角色MOD表[#Headers],0)))*(_xlfn.DROP(INDEX(角色MOD表[],MATCH($E14,角色MOD表[名称],0),),,MATCH("耐受",角色MOD表[#Headers],0))<>"")<>0),ROUNDUP(COLUMNS($L14:L14)/2,0))),_xlfn.LAMBDA(_xlpm.x,IFERROR(IF(ISNUMBER(MATCH($F14,{"百首","狮鹫","契约者"},0)),1+SUM(IFERROR(BUFF层数乘数*VLOOKUP(BUFF,BUFF表[],MATCH("MOD属性",BUFF表[#Headers],0),0),0)),1)*MIN(1,($J14+1)/IF($G14="金",11,IF($G14="绿",4,6)))*_xlpm.x,_xlpm.x))),"")} -> 0.44792 | N14: {=IFERROR(INDEX(角色MOD表[#Headers],SMALL(_xlfn._xlws.FILTER(COLUMN(_xlfn.DROP(INDEX(角色MOD表[],MATCH($E14,角色MOD表[名称],0),),,MATCH("耐受",角色MOD表[#Headers],0)))*(_xlfn.DROP(INDEX(角色MOD表[],MATCH($E14,角色MOD表[名称],0),),,6)<>""),COLUMN(_xlfn.DROP(INDEX(角色MOD表[],MATCH($E14,角色MOD表[名称],0),),,MATCH("耐受",角色MOD表[#Headers],0)))*(_xlfn.DROP(INDEX(角色MOD表[],MATCH($E14,角色MOD表[名称],0),),,6)<>"")<>0),ROUNDUP(COLUMNS($L14:N14)/2,0))),"")} -> 攻击 | O14: {=IFERROR(_xlfn.MAP(INDEX(INDEX(角色MOD表[],MATCH($E14,角色MOD表[名称],0),),SMALL(_xlfn._xlws.FILTER(COLUMN(_xlfn.DROP(INDEX(角色MOD表[],MATCH($E14,角色MOD表[名称],0),),,MATCH("耐受",角色MOD表[#Headers],0)))*(_xlfn.DROP(INDEX(角色MOD表[],MATCH($E14,角色MOD表[名称],0),),,MATCH("耐受",角色MOD表[#Headers],0))<>""),COLUMN(_xlfn.DROP(INDEX(角色MOD表[],MATCH($E14,角色MOD表[名称],0),),,MATCH("耐受",角色MOD表[#Headers],0)))*(_xlfn.DROP(INDEX(角色MOD表[],MATCH($E14,角色MOD表[名称],0),),,MATCH("耐受",角色MOD表[#Headers],0))<>"")<>0),ROUNDUP(COLUMNS($L14:N14)/2,0))),_xlfn.LAMBDA(_xlpm.x,IFERROR(IF(ISNUMBER(MATCH($F14,{"百首","狮鹫","契约者"},0)),1+SUM(IFERROR(BUFF层数乘数*VLOOKUP(BUFF,BUFF表[],MATCH("MOD属性",BUFF表[#Headers],0),0),0)),1)*MIN(1,($J14+1)/IF($G14="金",11,IF($G14="绿",4,6)))*_xlpm.x,_xlpm.x))),"")} -> 0.89584 | P14: {=IFERROR(INDEX(角色MOD表[#Headers],SMALL(_xlfn._xlws.FILTER(COLUMN(_xlfn.DROP(INDEX(角色MOD表[],MATCH($E14,角色MOD表[名称],0),),,MATCH("耐受",角色MOD表[#Headers],0)))*(_xlfn.DROP(INDEX(角色MOD表[],MATCH($E14,角色MOD表[名称],0),),,6)<>""),COLUMN(_xlfn.DROP(INDEX(角色MOD表[],MATCH($E14,角色MOD表[名称],0),),,MATCH("耐受",角色MOD表[#Headers],0)))*(_xlfn.DROP(INDEX(角色MOD表[],MATCH($E14,角色MOD表[名称],0),),,6)<>"")<>0),ROUNDUP(COLUMNS($L14:P14)/2,0))),"")} | Q14: {=IFERROR(_xlfn.MAP(INDEX(INDEX(角色MOD表[],MATCH($E14,角色MOD表[名称],0),),SMALL(_xlfn._xlws.FILTER(COLUMN(_xlfn.DROP(INDEX(角色MOD表[],MATCH($E14,角色MOD表[名称],0),),,MATCH("耐受",角色MOD表[#Headers],0)))*(_xlfn.DROP(INDEX(角色MOD表[],MATCH($E14,角色MOD表[名称],0),),,MATCH("耐受",角色MOD表[#Headers],0))<>""),COLUMN(_xlfn.DROP(INDEX(角色MOD表[],MATCH($E14,角色MOD表[名称],0),),,MATCH("耐受",角色MOD表[#Headers],0)))*(_xlfn.DROP(INDEX(角色MOD表[],MATCH($E14,角色MOD表[名称],0),),,MATCH("耐受",角色MOD表[#Headers],0))<>"")<>0),ROUNDUP(COLUMNS($L14:P14)/2,0))),_xlfn.LAMBDA(_xlpm.x,IFERROR(IF(ISNUMBER(MATCH($F14,{"百首","狮鹫","契约者"},0)),1+SUM(IFERROR(BUFF层数乘数*VLOOKUP(BUFF,BUFF表[],MATCH("MOD属性",BUFF表[#Headers],0),0),0)),1)*MIN(1,($J14+1)/IF($G14="金",11,IF($G14="绿",4,6)))*_xlpm.x,_xlpm.x))),"")} | R14: {=IFERROR(INDEX(角色MOD表[#Headers],SMALL(_xlfn._xlws.FILTER(COLUMN(_xlfn.DROP(INDEX(角色MOD表[],MATCH($E14,角色MOD表[名称],0),),,MATCH("耐受",角色MOD表[#Headers],0)))*(_xlfn.DROP(INDEX(角色MOD表[],MATCH($E14,角色MOD表[名称],0),),,6)<>""),COLUMN(_xlfn.DROP(INDEX(角色MOD表[],MATCH($E14,角色MOD表[名称],0),),,MATCH("耐受",角色MOD表[#Headers],0)))*(_xlfn.DROP(INDEX(角色MOD表[],MATCH($E14,角色MOD表[名称],0),),,6)<>"")<>0),ROUNDUP(COLUMNS($L14:R14)/2,0))),"")} | S14: {=IFERROR(_xlfn.MAP(INDEX(INDEX(角色MOD表[],MATCH($E14,角色MOD表[名称],0),),SMALL(_xlfn._xlws.FILTER(COLUMN(_xlfn.DROP(INDEX(角色MOD表[],MATCH($E14,角色MOD表[名称],0),),,MATCH("耐受",角色MOD表[#Headers],0)))*(_xlfn.DROP(INDEX(角色MOD表[],MATCH($E14,角色MOD表[名称],0),),,MATCH("耐受",角色MOD表[#Headers],0))<>""),COLUMN(_xlfn.DROP(INDEX(角色MOD表[],MATCH($E14,角色MOD表[名称],0),),,MATCH("耐受",角色MOD表[#Headers],0)))*(_xlfn.DROP(INDEX(角色MOD表[],MATCH($E14,角色MOD表[名称],0),),,MATCH("耐受",角色MOD表[#Headers],0))<>"")<>0),ROUNDUP(COLUMNS($L14:R14)/2,0))),_xlfn.LAMBDA(_xlpm.x,IFERROR(IF(ISNUMBER(MATCH($F14,{"百首","狮鹫","契约者"},0)),1+SUM(IFERROR(BUFF层数乘数*VLOOKUP(BUFF,BUFF表[],MATCH("MOD属性",BUFF表[#Headers],0),0),0)),1)*MIN(1,($J14+1)/IF($G14="金",11,IF($G14="绿",4,6)))*_xlpm.x,_xlpm.x))),"")} | T14: {=X14*SUM(B$24*U14,B$26*V14,B$25*W14,B$27)*昂扬背水乘区(AB14,AC14)*SUM(1,AD14,AE14)*(1-敌方抗性+AF14)*(1+AG14)/IF($A$39="DPMP",ROUNDUP($B$30*(2-Z14),0),1)/IF($A$39="DPSMP",ROUNDUP($B$31*MAX(0.25,(2-Z14)/Y14),0),1)*防御乘区(AH14)} -> 768463.32 | U14: {=删MOD取角色属性(U$6,ROWS($J$7:$J14))*(1+删MOD取角色属性("属性伤",ROWS($J$7:$J14)))} -> 5616.3875 | V14: {=删MOD取角色属性(V$6,ROWS($J$7:$J14))} -> 3388.6505 | W14: {=删MOD取角色属性(W$6,ROWS($J$7:$J14))} -> 971.49024 | X14: {=删MOD取角色属性(X$6,ROWS($J$7:$J14))} -> 7.56762 | Y14: {=删MOD取角色属性(Y$6,ROWS($J$7:$J14))} -> 1.2 | Z14: {=删MOD取角色属性(Z$6,ROWS($J$7:$J14))} -> 0 | AA14: {=删MOD取角色属性(AA$6,ROWS($J$7:$J14))} -> 1.33594 | AB14: {=删MOD取角色属性(AB$6,ROWS($J$7:$J14))} -> 0 | AC14: {=删MOD取角色属性(AC$6,ROWS($J$7:$J14))} -> 0.83008 | ... AH14: {=删MOD取角色属性(AH$6,ROWS($J$7:$J14))} -> 0 | AV14: 炽灼·决断 | AW14: 迅捷蓄势 | AX14: 专注·厚重
A15: 范围 | B15: =1+IFERROR(VLOOKUP($B$3,角色表[],MATCH(A15,角色表[#Headers],0),0),0) -> 1 | C15: {=取角色总属性(A15)} -> 1.33594 | D15: {=PRODUCT(D7:D14+1)-1} -> 3.3206895 | E15: 耐受 | F15: =SUM(7,I7:I14)&"/117" -> 155/117 | J15: 极化次数 | K15: =LEN(_xlfn.CONCAT(K7:K14)) -> 0 | L15: 中枢 | M15: 警惕 | AV15: 羽翼·永恒 | AW15: 迅捷闪击 | AX15: 迅捷·狡黠
A16: 昂扬 | B16: =IFERROR(VLOOKUP($B$3,角色表[],MATCH(A16,角色表[#Headers],0),0),0) -> 0 | C16: {=取角色总属性(A16)} -> 0 | D16: 社区代码 | E16: {=_xlfn.TEXTJOIN("",1,"C",IFERROR(INDEX(代码表[代码],MATCH(B3,代码表[名称],0),0),"0000"),_xlfn.MAP(_xlfn.VSTACK(_xlfn.MAP(TRANSPOSE({1,4,2,3,5,8,6,7}),_xlfn.LAMBDA(_xlpm.x,ADDRESS(ROW()-10+_xlpm.x,COLUMN()))),"M15"),_xlfn.LAMBDA(_xlpm.x,IFERROR(INDEX(#REF!,MATCH(1,((代码表[属性]=B6)+(代码表[属性]=""))*((代码表[品质]=OFFSET(INDIRECT(_xlpm.x),0,2))+(OFFSET(INDIRECT(_xlpm.x),0,2)=""))*(代码表[名称]=IF(ISNUMBER(FIND("(",INDIRECT(_xlpm.x))),LEFT(INDIRECT(_xlpm.x),FIND("(",INDIRECT(_xlpm.x))-1),INDIRECT(_xlpm.x))),0),MATCH("代码",代码表[#Headers],0)),"0000"))))} -> C0439000000000000000000000000000000000000 | AV16: 炽灼·背水 | AW16: 残影 | AX16: 整备
A17: 背水 | B17: =IFERROR(VLOOKUP($B$3,角色表[],MATCH(A17,角色表[#Headers],0),0),0) -> 0.05 | C17: {=取角色总属性(A17)} -> 0.83008 | D17: 增益效果 | AV17: 炽灼·坚守 | AW17: 巡游 | AX17: 俭约
